2025-03-17 15:15:17,533 - ERROR - Une erreur est survenue
Traceback (most recent call last):
  File "c:\Users\LENOVO\Desktop\Academy\main.py", line 444, in generer_word
    row_cells[j].text = text
  File "C:\Users\LENOVO\Desktop\Academy\env\lib\site-packages\docx\table.py", line 284, in text
    r.text = text
  File "C:\Users\LENOVO\Desktop\Academy\env\lib\site-packages\docx\oxml\text\run.py", line 129, in text
    _RunContentAppender.append_to_run_from_text(self, text)
  File "C:\Users\LENOVO\Desktop\Academy\env\lib\site-packages\docx\oxml\text\run.py", line 248, in append_to_run_from_text
    appender.add_text(text)
  File "C:\Users\LENOVO\Desktop\Academy\env\lib\site-packages\docx\oxml\text\run.py", line 252, in add_text
    for char in text:
TypeError: 'NoneType' object is not iterable
2025-03-17 15:15:17,597 - ERROR - Une erreur est survenue
Traceback (most recent call last):
  File "c:\Users\LENOVO\Desktop\Academy\main.py", line 444, in generer_word
    row_cells[j].text = text
  File "C:\Users\LENOVO\Desktop\Academy\env\lib\site-packages\docx\table.py", line 284, in text
    r.text = text
  File "C:\Users\LENOVO\Desktop\Academy\env\lib\site-packages\docx\oxml\text\run.py", line 129, in text
    _RunContentAppender.append_to_run_from_text(self, text)
  File "C:\Users\LENOVO\Desktop\Academy\env\lib\site-packages\docx\oxml\text\run.py", line 248, in append_to_run_from_text
    appender.add_text(text)
  File "C:\Users\LENOVO\Desktop\Academy\env\lib\site-packages\docx\oxml\text\run.py", line 252, in add_text
    for char in text:
TypeError: 'NoneType' object is not iterable
2025-03-17 15:15:17,628 - ERROR - Une erreur est survenue
Traceback (most recent call last):
  File "c:\Users\LENOVO\Desktop\Academy\main.py", line 444, in generer_word
    row_cells[j].text = text
  File "C:\Users\LENOVO\Desktop\Academy\env\lib\site-packages\docx\table.py", line 284, in text
    r.text = text
  File "C:\Users\LENOVO\Desktop\Academy\env\lib\site-packages\docx\oxml\text\run.py", line 129, in text
    _RunContentAppender.append_to_run_from_text(self, text)
  File "C:\Users\LENOVO\Desktop\Academy\env\lib\site-packages\docx\oxml\text\run.py", line 248, in append_to_run_from_text
    appender.add_text(text)
  File "C:\Users\LENOVO\Desktop\Academy\env\lib\site-packages\docx\oxml\text\run.py", line 252, in add_text
    for char in text:
TypeError: 'NoneType' object is not iterable
2025-03-17 15:15:17,674 - ERROR - Une erreur est survenue
Traceback (most recent call last):
  File "c:\Users\LENOVO\Desktop\Academy\main.py", line 444, in generer_word
    row_cells[j].text = text
  File "C:\Users\LENOVO\Desktop\Academy\env\lib\site-packages\docx\table.py", line 284, in text
    r.text = text
  File "C:\Users\LENOVO\Desktop\Academy\env\lib\site-packages\docx\oxml\text\run.py", line 129, in text
    _RunContentAppender.append_to_run_from_text(self, text)
  File "C:\Users\LENOVO\Desktop\Academy\env\lib\site-packages\docx\oxml\text\run.py", line 248, in append_to_run_from_text
    appender.add_text(text)
  File "C:\Users\LENOVO\Desktop\Academy\env\lib\site-packages\docx\oxml\text\run.py", line 252, in add_text
    for char in text:
TypeError: 'NoneType' object is not iterable
2025-03-17 15:15:19,465 - ERROR - Une erreur est survenue
Traceback (most recent call last):
  File "c:\Users\LENOVO\Desktop\Academy\main.py", line 444, in generer_word
    row_cells[j].text = text
  File "C:\Users\LENOVO\Desktop\Academy\env\lib\site-packages\docx\table.py", line 284, in text
    r.text = text
  File "C:\Users\LENOVO\Desktop\Academy\env\lib\site-packages\docx\oxml\text\run.py", line 129, in text
    _RunContentAppender.append_to_run_from_text(self, text)
  File "C:\Users\LENOVO\Desktop\Academy\env\lib\site-packages\docx\oxml\text\run.py", line 248, in append_to_run_from_text
    appender.add_text(text)
  File "C:\Users\LENOVO\Desktop\Academy\env\lib\site-packages\docx\oxml\text\run.py", line 252, in add_text
    for char in text:
TypeError: 'NoneType' object is not iterable
2025-03-17 15:15:19,516 - ERROR - Une erreur est survenue
Traceback (most recent call last):
  File "c:\Users\LENOVO\Desktop\Academy\main.py", line 444, in generer_word
    row_cells[j].text = text
  File "C:\Users\LENOVO\Desktop\Academy\env\lib\site-packages\docx\table.py", line 284, in text
    r.text = text
  File "C:\Users\LENOVO\Desktop\Academy\env\lib\site-packages\docx\oxml\text\run.py", line 129, in text
    _RunContentAppender.append_to_run_from_text(self, text)
  File "C:\Users\LENOVO\Desktop\Academy\env\lib\site-packages\docx\oxml\text\run.py", line 248, in append_to_run_from_text
    appender.add_text(text)
  File "C:\Users\LENOVO\Desktop\Academy\env\lib\site-packages\docx\oxml\text\run.py", line 252, in add_text
    for char in text:
TypeError: 'NoneType' object is not iterable
2025-03-17 15:15:19,550 - ERROR - Une erreur est survenue
Traceback (most recent call last):
  File "c:\Users\LENOVO\Desktop\Academy\main.py", line 444, in generer_word
    row_cells[j].text = text
  File "C:\Users\LENOVO\Desktop\Academy\env\lib\site-packages\docx\table.py", line 284, in text
    r.text = text
  File "C:\Users\LENOVO\Desktop\Academy\env\lib\site-packages\docx\oxml\text\run.py", line 129, in text
    _RunContentAppender.append_to_run_from_text(self, text)
  File "C:\Users\LENOVO\Desktop\Academy\env\lib\site-packages\docx\oxml\text\run.py", line 248, in append_to_run_from_text
    appender.add_text(text)
  File "C:\Users\LENOVO\Desktop\Academy\env\lib\site-packages\docx\oxml\text\run.py", line 252, in add_text
    for char in text:
TypeError: 'NoneType' object is not iterable
2025-03-17 15:15:19,583 - ERROR - Une erreur est survenue
Traceback (most recent call last):
  File "c:\Users\LENOVO\Desktop\Academy\main.py", line 444, in generer_word
    row_cells[j].text = text
  File "C:\Users\LENOVO\Desktop\Academy\env\lib\site-packages\docx\table.py", line 284, in text
    r.text = text
  File "C:\Users\LENOVO\Desktop\Academy\env\lib\site-packages\docx\oxml\text\run.py", line 129, in text
    _RunContentAppender.append_to_run_from_text(self, text)
  File "C:\Users\LENOVO\Desktop\Academy\env\lib\site-packages\docx\oxml\text\run.py", line 248, in append_to_run_from_text
    appender.add_text(text)
  File "C:\Users\LENOVO\Desktop\Academy\env\lib\site-packages\docx\oxml\text\run.py", line 252, in add_text
    for char in text:
TypeError: 'NoneType' object is not iterable
2025-03-17 15:15:19,626 - ERROR - Une erreur est survenue
Traceback (most recent call last):
  File "c:\Users\LENOVO\Desktop\Academy\main.py", line 444, in generer_word
    row_cells[j].text = text
  File "C:\Users\LENOVO\Desktop\Academy\env\lib\site-packages\docx\table.py", line 284, in text
    r.text = text
  File "C:\Users\LENOVO\Desktop\Academy\env\lib\site-packages\docx\oxml\text\run.py", line 129, in text
    _RunContentAppender.append_to_run_from_text(self, text)
  File "C:\Users\LENOVO\Desktop\Academy\env\lib\site-packages\docx\oxml\text\run.py", line 248, in append_to_run_from_text
    appender.add_text(text)
  File "C:\Users\LENOVO\Desktop\Academy\env\lib\site-packages\docx\oxml\text\run.py", line 252, in add_text
    for char in text:
TypeError: 'NoneType' object is not iterable
2025-03-17 15:15:19,665 - ERROR - Une erreur est survenue
Traceback (most recent call last):
  File "c:\Users\LENOVO\Desktop\Academy\main.py", line 444, in generer_word
    row_cells[j].text = text
  File "C:\Users\LENOVO\Desktop\Academy\env\lib\site-packages\docx\table.py", line 284, in text
    r.text = text
  File "C:\Users\LENOVO\Desktop\Academy\env\lib\site-packages\docx\oxml\text\run.py", line 129, in text
    _RunContentAppender.append_to_run_from_text(self, text)
  File "C:\Users\LENOVO\Desktop\Academy\env\lib\site-packages\docx\oxml\text\run.py", line 248, in append_to_run_from_text
    appender.add_text(text)
  File "C:\Users\LENOVO\Desktop\Academy\env\lib\site-packages\docx\oxml\text\run.py", line 252, in add_text
    for char in text:
TypeError: 'NoneType' object is not iterable
2025-03-17 15:15:19,709 - ERROR - Une erreur est survenue
Traceback (most recent call last):
  File "c:\Users\LENOVO\Desktop\Academy\main.py", line 444, in generer_word
    row_cells[j].text = text
  File "C:\Users\LENOVO\Desktop\Academy\env\lib\site-packages\docx\table.py", line 284, in text
    r.text = text
  File "C:\Users\LENOVO\Desktop\Academy\env\lib\site-packages\docx\oxml\text\run.py", line 129, in text
    _RunContentAppender.append_to_run_from_text(self, text)
  File "C:\Users\LENOVO\Desktop\Academy\env\lib\site-packages\docx\oxml\text\run.py", line 248, in append_to_run_from_text
    appender.add_text(text)
  File "C:\Users\LENOVO\Desktop\Academy\env\lib\site-packages\docx\oxml\text\run.py", line 252, in add_text
    for char in text:
TypeError: 'NoneType' object is not iterable
2025-03-17 15:15:19,752 - ERROR - Une erreur est survenue
Traceback (most recent call last):
  File "c:\Users\LENOVO\Desktop\Academy\main.py", line 444, in generer_word
    row_cells[j].text = text
  File "C:\Users\LENOVO\Desktop\Academy\env\lib\site-packages\docx\table.py", line 284, in text
    r.text = text
  File "C:\Users\LENOVO\Desktop\Academy\env\lib\site-packages\docx\oxml\text\run.py", line 129, in text
    _RunContentAppender.append_to_run_from_text(self, text)
  File "C:\Users\LENOVO\Desktop\Academy\env\lib\site-packages\docx\oxml\text\run.py", line 248, in append_to_run_from_text
    appender.add_text(text)
  File "C:\Users\LENOVO\Desktop\Academy\env\lib\site-packages\docx\oxml\text\run.py", line 252, in add_text
    for char in text:
TypeError: 'NoneType' object is not iterable
2025-03-17 15:15:19,788 - ERROR - Une erreur est survenue
Traceback (most recent call last):
  File "c:\Users\LENOVO\Desktop\Academy\main.py", line 444, in generer_word
    row_cells[j].text = text
  File "C:\Users\LENOVO\Desktop\Academy\env\lib\site-packages\docx\table.py", line 284, in text
    r.text = text
  File "C:\Users\LENOVO\Desktop\Academy\env\lib\site-packages\docx\oxml\text\run.py", line 129, in text
    _RunContentAppender.append_to_run_from_text(self, text)
  File "C:\Users\LENOVO\Desktop\Academy\env\lib\site-packages\docx\oxml\text\run.py", line 248, in append_to_run_from_text
    appender.add_text(text)
  File "C:\Users\LENOVO\Desktop\Academy\env\lib\site-packages\docx\oxml\text\run.py", line 252, in add_text
    for char in text:
TypeError: 'NoneType' object is not iterable
2025-03-17 15:15:19,813 - ERROR - Une erreur est survenue
Traceback (most recent call last):
  File "c:\Users\LENOVO\Desktop\Academy\main.py", line 444, in generer_word
    row_cells[j].text = text
  File "C:\Users\LENOVO\Desktop\Academy\env\lib\site-packages\docx\table.py", line 284, in text
    r.text = text
  File "C:\Users\LENOVO\Desktop\Academy\env\lib\site-packages\docx\oxml\text\run.py", line 129, in text
    _RunContentAppender.append_to_run_from_text(self, text)
  File "C:\Users\LENOVO\Desktop\Academy\env\lib\site-packages\docx\oxml\text\run.py", line 248, in append_to_run_from_text
    appender.add_text(text)
  File "C:\Users\LENOVO\Desktop\Academy\env\lib\site-packages\docx\oxml\text\run.py", line 252, in add_text
    for char in text:
TypeError: 'NoneType' object is not iterable
2025-03-17 15:15:19,856 - ERROR - Une erreur est survenue
Traceback (most recent call last):
  File "c:\Users\LENOVO\Desktop\Academy\main.py", line 444, in generer_word
    row_cells[j].text = text
  File "C:\Users\LENOVO\Desktop\Academy\env\lib\site-packages\docx\table.py", line 284, in text
    r.text = text
  File "C:\Users\LENOVO\Desktop\Academy\env\lib\site-packages\docx\oxml\text\run.py", line 129, in text
    _RunContentAppender.append_to_run_from_text(self, text)
  File "C:\Users\LENOVO\Desktop\Academy\env\lib\site-packages\docx\oxml\text\run.py", line 248, in append_to_run_from_text
    appender.add_text(text)
  File "C:\Users\LENOVO\Desktop\Academy\env\lib\site-packages\docx\oxml\text\run.py", line 252, in add_text
    for char in text:
TypeError: 'NoneType' object is not iterable
2025-03-17 15:15:19,893 - ERROR - Une erreur est survenue
Traceback (most recent call last):
  File "c:\Users\LENOVO\Desktop\Academy\main.py", line 444, in generer_word
    row_cells[j].text = text
  File "C:\Users\LENOVO\Desktop\Academy\env\lib\site-packages\docx\table.py", line 284, in text
    r.text = text
  File "C:\Users\LENOVO\Desktop\Academy\env\lib\site-packages\docx\oxml\text\run.py", line 129, in text
    _RunContentAppender.append_to_run_from_text(self, text)
  File "C:\Users\LENOVO\Desktop\Academy\env\lib\site-packages\docx\oxml\text\run.py", line 248, in append_to_run_from_text
    appender.add_text(text)
  File "C:\Users\LENOVO\Desktop\Academy\env\lib\site-packages\docx\oxml\text\run.py", line 252, in add_text
    for char in text:
TypeError: 'NoneType' object is not iterable
2025-03-17 15:15:19,893 - ERROR - Une erreur est survenue
Traceback (most recent call last):
  File "c:\Users\LENOVO\Desktop\Academy\main.py", line 444, in generer_word
    row_cells[j].text = text
  File "C:\Users\LENOVO\Desktop\Academy\env\lib\site-packages\docx\table.py", line 284, in text
    r.text = text
  File "C:\Users\LENOVO\Desktop\Academy\env\lib\site-packages\docx\oxml\text\run.py", line 129, in text
    _RunContentAppender.append_to_run_from_text(self, text)
  File "C:\Users\LENOVO\Desktop\Academy\env\lib\site-packages\docx\oxml\text\run.py", line 248, in append_to_run_from_text
    appender.add_text(text)
  File "C:\Users\LENOVO\Desktop\Academy\env\lib\site-packages\docx\oxml\text\run.py", line 252, in add_text
    for char in text:
TypeError: 'NoneType' object is not iterable
2025-03-17 15:15:19,932 - ERROR - Une erreur est survenue
Traceback (most recent call last):
  File "c:\Users\LENOVO\Desktop\Academy\main.py", line 444, in generer_word
    row_cells[j].text = text
  File "C:\Users\LENOVO\Desktop\Academy\env\lib\site-packages\docx\table.py", line 284, in text
    r.text = text
  File "C:\Users\LENOVO\Desktop\Academy\env\lib\site-packages\docx\oxml\text\run.py", line 129, in text
    _RunContentAppender.append_to_run_from_text(self, text)
  File "C:\Users\LENOVO\Desktop\Academy\env\lib\site-packages\docx\oxml\text\run.py", line 248, in append_to_run_from_text
    appender.add_text(text)
  File "C:\Users\LENOVO\Desktop\Academy\env\lib\site-packages\docx\oxml\text\run.py", line 252, in add_text
    for char in text:
TypeError: 'NoneType' object is not iterable
2025-03-17 15:15:19,966 - ERROR - Une erreur est survenue
Traceback (most recent call last):
  File "c:\Users\LENOVO\Desktop\Academy\main.py", line 444, in generer_word
    row_cells[j].text = text
  File "C:\Users\LENOVO\Desktop\Academy\env\lib\site-packages\docx\table.py", line 284, in text
    r.text = text
  File "C:\Users\LENOVO\Desktop\Academy\env\lib\site-packages\docx\oxml\text\run.py", line 129, in text
    _RunContentAppender.append_to_run_from_text(self, text)
  File "C:\Users\LENOVO\Desktop\Academy\env\lib\site-packages\docx\oxml\text\run.py", line 248, in append_to_run_from_text
    appender.add_text(text)
  File "C:\Users\LENOVO\Desktop\Academy\env\lib\site-packages\docx\oxml\text\run.py", line 252, in add_text
    for char in text:
TypeError: 'NoneType' object is not iterable
2025-03-17 15:15:20,004 - ERROR - Une erreur est survenue
Traceback (most recent call last):
  File "c:\Users\LENOVO\Desktop\Academy\main.py", line 444, in generer_word
    row_cells[j].text = text
  File "C:\Users\LENOVO\Desktop\Academy\env\lib\site-packages\docx\table.py", line 284, in text
    r.text = text
  File "C:\Users\LENOVO\Desktop\Academy\env\lib\site-packages\docx\oxml\text\run.py", line 129, in text
    _RunContentAppender.append_to_run_from_text(self, text)
  File "C:\Users\LENOVO\Desktop\Academy\env\lib\site-packages\docx\oxml\text\run.py", line 248, in append_to_run_from_text
    appender.add_text(text)
  File "C:\Users\LENOVO\Desktop\Academy\env\lib\site-packages\docx\oxml\text\run.py", line 252, in add_text
    for char in text:
TypeError: 'NoneType' object is not iterable
2025-03-17 15:15:20,049 - ERROR - Une erreur est survenue
Traceback (most recent call last):
  File "c:\Users\LENOVO\Desktop\Academy\main.py", line 444, in generer_word
    row_cells[j].text = text
  File "C:\Users\LENOVO\Desktop\Academy\env\lib\site-packages\docx\table.py", line 284, in text
    r.text = text
  File "C:\Users\LENOVO\Desktop\Academy\env\lib\site-packages\docx\oxml\text\run.py", line 129, in text
    _RunContentAppender.append_to_run_from_text(self, text)
  File "C:\Users\LENOVO\Desktop\Academy\env\lib\site-packages\docx\oxml\text\run.py", line 248, in append_to_run_from_text
    appender.add_text(text)
  File "C:\Users\LENOVO\Desktop\Academy\env\lib\site-packages\docx\oxml\text\run.py", line 252, in add_text
    for char in text:
TypeError: 'NoneType' object is not iterable
2025-03-17 15:15:20,093 - ERROR - Une erreur est survenue
Traceback (most recent call last):
  File "c:\Users\LENOVO\Desktop\Academy\main.py", line 444, in generer_word
    row_cells[j].text = text
  File "C:\Users\LENOVO\Desktop\Academy\env\lib\site-packages\docx\table.py", line 284, in text
    r.text = text
  File "C:\Users\LENOVO\Desktop\Academy\env\lib\site-packages\docx\oxml\text\run.py", line 129, in text
    _RunContentAppender.append_to_run_from_text(self, text)
  File "C:\Users\LENOVO\Desktop\Academy\env\lib\site-packages\docx\oxml\text\run.py", line 248, in append_to_run_from_text
    appender.add_text(text)
  File "C:\Users\LENOVO\Desktop\Academy\env\lib\site-packages\docx\oxml\text\run.py", line 252, in add_text
    for char in text:
TypeError: 'NoneType' object is not iterable
2025-03-17 15:15:20,126 - ERROR - Une erreur est survenue
Traceback (most recent call last):
  File "c:\Users\LENOVO\Desktop\Academy\main.py", line 444, in generer_word
    row_cells[j].text = text
  File "C:\Users\LENOVO\Desktop\Academy\env\lib\site-packages\docx\table.py", line 284, in text
    r.text = text
  File "C:\Users\LENOVO\Desktop\Academy\env\lib\site-packages\docx\oxml\text\run.py", line 129, in text
    _RunContentAppender.append_to_run_from_text(self, text)
  File "C:\Users\LENOVO\Desktop\Academy\env\lib\site-packages\docx\oxml\text\run.py", line 248, in append_to_run_from_text
    appender.add_text(text)
  File "C:\Users\LENOVO\Desktop\Academy\env\lib\site-packages\docx\oxml\text\run.py", line 252, in add_text
    for char in text:
TypeError: 'NoneType' object is not iterable
2025-03-17 15:15:20,160 - ERROR - Une erreur est survenue
Traceback (most recent call last):
  File "c:\Users\LENOVO\Desktop\Academy\main.py", line 444, in generer_word
    row_cells[j].text = text
  File "C:\Users\LENOVO\Desktop\Academy\env\lib\site-packages\docx\table.py", line 284, in text
    r.text = text
  File "C:\Users\LENOVO\Desktop\Academy\env\lib\site-packages\docx\oxml\text\run.py", line 129, in text
    _RunContentAppender.append_to_run_from_text(self, text)
  File "C:\Users\LENOVO\Desktop\Academy\env\lib\site-packages\docx\oxml\text\run.py", line 248, in append_to_run_from_text
    appender.add_text(text)
  File "C:\Users\LENOVO\Desktop\Academy\env\lib\site-packages\docx\oxml\text\run.py", line 252, in add_text
    for char in text:
TypeError: 'NoneType' object is not iterable
2025-03-17 15:15:20,230 - ERROR - Une erreur est survenue
Traceback (most recent call last):
  File "c:\Users\LENOVO\Desktop\Academy\main.py", line 444, in generer_word
    row_cells[j].text = text
  File "C:\Users\LENOVO\Desktop\Academy\env\lib\site-packages\docx\table.py", line 284, in text
    r.text = text
  File "C:\Users\LENOVO\Desktop\Academy\env\lib\site-packages\docx\oxml\text\run.py", line 129, in text
    _RunContentAppender.append_to_run_from_text(self, text)
  File "C:\Users\LENOVO\Desktop\Academy\env\lib\site-packages\docx\oxml\text\run.py", line 248, in append_to_run_from_text
    appender.add_text(text)
  File "C:\Users\LENOVO\Desktop\Academy\env\lib\site-packages\docx\oxml\text\run.py", line 252, in add_text
    for char in text:
TypeError: 'NoneType' object is not iterable
2025-03-17 15:15:20,265 - ERROR - Une erreur est survenue
Traceback (most recent call last):
  File "c:\Users\LENOVO\Desktop\Academy\main.py", line 444, in generer_word
    row_cells[j].text = text
  File "C:\Users\LENOVO\Desktop\Academy\env\lib\site-packages\docx\table.py", line 284, in text
    r.text = text
  File "C:\Users\LENOVO\Desktop\Academy\env\lib\site-packages\docx\oxml\text\run.py", line 129, in text
    _RunContentAppender.append_to_run_from_text(self, text)
  File "C:\Users\LENOVO\Desktop\Academy\env\lib\site-packages\docx\oxml\text\run.py", line 248, in append_to_run_from_text
    appender.add_text(text)
  File "C:\Users\LENOVO\Desktop\Academy\env\lib\site-packages\docx\oxml\text\run.py", line 252, in add_text
    for char in text:
TypeError: 'NoneType' object is not iterable
2025-03-17 15:15:20,332 - ERROR - Une erreur est survenue
Traceback (most recent call last):
  File "c:\Users\LENOVO\Desktop\Academy\main.py", line 444, in generer_word
    row_cells[j].text = text
  File "C:\Users\LENOVO\Desktop\Academy\env\lib\site-packages\docx\table.py", line 284, in text
    r.text = text
  File "C:\Users\LENOVO\Desktop\Academy\env\lib\site-packages\docx\oxml\text\run.py", line 129, in text
    _RunContentAppender.append_to_run_from_text(self, text)
  File "C:\Users\LENOVO\Desktop\Academy\env\lib\site-packages\docx\oxml\text\run.py", line 248, in append_to_run_from_text
    appender.add_text(text)
  File "C:\Users\LENOVO\Desktop\Academy\env\lib\site-packages\docx\oxml\text\run.py", line 252, in add_text
    for char in text:
TypeError: 'NoneType' object is not iterable
2025-03-17 15:15:20,366 - ERROR - Une erreur est survenue
Traceback (most recent call last):
  File "c:\Users\LENOVO\Desktop\Academy\main.py", line 444, in generer_word
    row_cells[j].text = text
  File "C:\Users\LENOVO\Desktop\Academy\env\lib\site-packages\docx\table.py", line 284, in text
    r.text = text
  File "C:\Users\LENOVO\Desktop\Academy\env\lib\site-packages\docx\oxml\text\run.py", line 129, in text
    _RunContentAppender.append_to_run_from_text(self, text)
  File "C:\Users\LENOVO\Desktop\Academy\env\lib\site-packages\docx\oxml\text\run.py", line 248, in append_to_run_from_text
    appender.add_text(text)
  File "C:\Users\LENOVO\Desktop\Academy\env\lib\site-packages\docx\oxml\text\run.py", line 252, in add_text
    for char in text:
TypeError: 'NoneType' object is not iterable
2025-03-17 15:15:20,402 - ERROR - Une erreur est survenue
Traceback (most recent call last):
  File "c:\Users\LENOVO\Desktop\Academy\main.py", line 444, in generer_word
    row_cells[j].text = text
  File "C:\Users\LENOVO\Desktop\Academy\env\lib\site-packages\docx\table.py", line 284, in text
    r.text = text
  File "C:\Users\LENOVO\Desktop\Academy\env\lib\site-packages\docx\oxml\text\run.py", line 129, in text
    _RunContentAppender.append_to_run_from_text(self, text)
  File "C:\Users\LENOVO\Desktop\Academy\env\lib\site-packages\docx\oxml\text\run.py", line 248, in append_to_run_from_text
    appender.add_text(text)
  File "C:\Users\LENOVO\Desktop\Academy\env\lib\site-packages\docx\oxml\text\run.py", line 252, in add_text
    for char in text:
TypeError: 'NoneType' object is not iterable
2025-03-17 15:15:20,446 - ERROR - Une erreur est survenue
Traceback (most recent call last):
  File "c:\Users\LENOVO\Desktop\Academy\main.py", line 444, in generer_word
    row_cells[j].text = text
  File "C:\Users\LENOVO\Desktop\Academy\env\lib\site-packages\docx\table.py", line 284, in text
    r.text = text
  File "C:\Users\LENOVO\Desktop\Academy\env\lib\site-packages\docx\oxml\text\run.py", line 129, in text
    _RunContentAppender.append_to_run_from_text(self, text)
  File "C:\Users\LENOVO\Desktop\Academy\env\lib\site-packages\docx\oxml\text\run.py", line 248, in append_to_run_from_text
    appender.add_text(text)
  File "C:\Users\LENOVO\Desktop\Academy\env\lib\site-packages\docx\oxml\text\run.py", line 252, in add_text
    for char in text:
TypeError: 'NoneType' object is not iterable
2025-03-17 15:15:20,476 - ERROR - Une erreur est survenue
Traceback (most recent call last):
  File "c:\Users\LENOVO\Desktop\Academy\main.py", line 444, in generer_word
    row_cells[j].text = text
  File "C:\Users\LENOVO\Desktop\Academy\env\lib\site-packages\docx\table.py", line 284, in text
    r.text = text
  File "C:\Users\LENOVO\Desktop\Academy\env\lib\site-packages\docx\oxml\text\run.py", line 129, in text
    _RunContentAppender.append_to_run_from_text(self, text)
  File "C:\Users\LENOVO\Desktop\Academy\env\lib\site-packages\docx\oxml\text\run.py", line 248, in append_to_run_from_text
    appender.add_text(text)
  File "C:\Users\LENOVO\Desktop\Academy\env\lib\site-packages\docx\oxml\text\run.py", line 252, in add_text
    for char in text:
TypeError: 'NoneType' object is not iterable
2025-03-17 15:15:20,510 - ERROR - Une erreur est survenue
Traceback (most recent call last):
  File "c:\Users\LENOVO\Desktop\Academy\main.py", line 444, in generer_word
    row_cells[j].text = text
  File "C:\Users\LENOVO\Desktop\Academy\env\lib\site-packages\docx\table.py", line 284, in text
    r.text = text
  File "C:\Users\LENOVO\Desktop\Academy\env\lib\site-packages\docx\oxml\text\run.py", line 129, in text
    _RunContentAppender.append_to_run_from_text(self, text)
  File "C:\Users\LENOVO\Desktop\Academy\env\lib\site-packages\docx\oxml\text\run.py", line 248, in append_to_run_from_text
    appender.add_text(text)
  File "C:\Users\LENOVO\Desktop\Academy\env\lib\site-packages\docx\oxml\text\run.py", line 252, in add_text
    for char in text:
TypeError: 'NoneType' object is not iterable
2025-03-17 15:15:20,543 - ERROR - Une erreur est survenue
Traceback (most recent call last):
  File "c:\Users\LENOVO\Desktop\Academy\main.py", line 444, in generer_word
    row_cells[j].text = text
  File "C:\Users\LENOVO\Desktop\Academy\env\lib\site-packages\docx\table.py", line 284, in text
    r.text = text
  File "C:\Users\LENOVO\Desktop\Academy\env\lib\site-packages\docx\oxml\text\run.py", line 129, in text
    _RunContentAppender.append_to_run_from_text(self, text)
  File "C:\Users\LENOVO\Desktop\Academy\env\lib\site-packages\docx\oxml\text\run.py", line 248, in append_to_run_from_text
    appender.add_text(text)
  File "C:\Users\LENOVO\Desktop\Academy\env\lib\site-packages\docx\oxml\text\run.py", line 252, in add_text
    for char in text:
TypeError: 'NoneType' object is not iterable
2025-03-17 15:15:20,576 - ERROR - Une erreur est survenue
Traceback (most recent call last):
  File "c:\Users\LENOVO\Desktop\Academy\main.py", line 444, in generer_word
    row_cells[j].text = text
  File "C:\Users\LENOVO\Desktop\Academy\env\lib\site-packages\docx\table.py", line 284, in text
    r.text = text
  File "C:\Users\LENOVO\Desktop\Academy\env\lib\site-packages\docx\oxml\text\run.py", line 129, in text
    _RunContentAppender.append_to_run_from_text(self, text)
  File "C:\Users\LENOVO\Desktop\Academy\env\lib\site-packages\docx\oxml\text\run.py", line 248, in append_to_run_from_text
    appender.add_text(text)
  File "C:\Users\LENOVO\Desktop\Academy\env\lib\site-packages\docx\oxml\text\run.py", line 252, in add_text
    for char in text:
TypeError: 'NoneType' object is not iterable
2025-03-17 15:15:20,610 - ERROR - Une erreur est survenue
Traceback (most recent call last):
  File "c:\Users\LENOVO\Desktop\Academy\main.py", line 444, in generer_word
    row_cells[j].text = text
  File "C:\Users\LENOVO\Desktop\Academy\env\lib\site-packages\docx\table.py", line 284, in text
    r.text = text
  File "C:\Users\LENOVO\Desktop\Academy\env\lib\site-packages\docx\oxml\text\run.py", line 129, in text
    _RunContentAppender.append_to_run_from_text(self, text)
  File "C:\Users\LENOVO\Desktop\Academy\env\lib\site-packages\docx\oxml\text\run.py", line 248, in append_to_run_from_text
    appender.add_text(text)
  File "C:\Users\LENOVO\Desktop\Academy\env\lib\site-packages\docx\oxml\text\run.py", line 252, in add_text
    for char in text:
TypeError: 'NoneType' object is not iterable
2025-03-17 15:15:20,612 - ERROR - Une erreur est survenue
Traceback (most recent call last):
  File "c:\Users\LENOVO\Desktop\Academy\main.py", line 444, in generer_word
    row_cells[j].text = text
  File "C:\Users\LENOVO\Desktop\Academy\env\lib\site-packages\docx\table.py", line 284, in text
    r.text = text
  File "C:\Users\LENOVO\Desktop\Academy\env\lib\site-packages\docx\oxml\text\run.py", line 129, in text
    _RunContentAppender.append_to_run_from_text(self, text)
  File "C:\Users\LENOVO\Desktop\Academy\env\lib\site-packages\docx\oxml\text\run.py", line 248, in append_to_run_from_text
    appender.add_text(text)
  File "C:\Users\LENOVO\Desktop\Academy\env\lib\site-packages\docx\oxml\text\run.py", line 252, in add_text
    for char in text:
TypeError: 'NoneType' object is not iterable
2025-03-17 15:15:20,643 - ERROR - Une erreur est survenue
Traceback (most recent call last):
  File "c:\Users\LENOVO\Desktop\Academy\main.py", line 444, in generer_word
    row_cells[j].text = text
  File "C:\Users\LENOVO\Desktop\Academy\env\lib\site-packages\docx\table.py", line 284, in text
    r.text = text
  File "C:\Users\LENOVO\Desktop\Academy\env\lib\site-packages\docx\oxml\text\run.py", line 129, in text
    _RunContentAppender.append_to_run_from_text(self, text)
  File "C:\Users\LENOVO\Desktop\Academy\env\lib\site-packages\docx\oxml\text\run.py", line 248, in append_to_run_from_text
    appender.add_text(text)
  File "C:\Users\LENOVO\Desktop\Academy\env\lib\site-packages\docx\oxml\text\run.py", line 252, in add_text
    for char in text:
TypeError: 'NoneType' object is not iterable
2025-03-17 15:15:20,676 - ERROR - Une erreur est survenue
Traceback (most recent call last):
  File "c:\Users\LENOVO\Desktop\Academy\main.py", line 444, in generer_word
    row_cells[j].text = text
  File "C:\Users\LENOVO\Desktop\Academy\env\lib\site-packages\docx\table.py", line 284, in text
    r.text = text
  File "C:\Users\LENOVO\Desktop\Academy\env\lib\site-packages\docx\oxml\text\run.py", line 129, in text
    _RunContentAppender.append_to_run_from_text(self, text)
  File "C:\Users\LENOVO\Desktop\Academy\env\lib\site-packages\docx\oxml\text\run.py", line 248, in append_to_run_from_text
    appender.add_text(text)
  File "C:\Users\LENOVO\Desktop\Academy\env\lib\site-packages\docx\oxml\text\run.py", line 252, in add_text
    for char in text:
TypeError: 'NoneType' object is not iterable
2025-03-17 15:15:20,749 - ERROR - Une erreur est survenue
Traceback (most recent call last):
  File "c:\Users\LENOVO\Desktop\Academy\main.py", line 444, in generer_word
    row_cells[j].text = text
  File "C:\Users\LENOVO\Desktop\Academy\env\lib\site-packages\docx\table.py", line 284, in text
    r.text = text
  File "C:\Users\LENOVO\Desktop\Academy\env\lib\site-packages\docx\oxml\text\run.py", line 129, in text
    _RunContentAppender.append_to_run_from_text(self, text)
  File "C:\Users\LENOVO\Desktop\Academy\env\lib\site-packages\docx\oxml\text\run.py", line 248, in append_to_run_from_text
    appender.add_text(text)
  File "C:\Users\LENOVO\Desktop\Academy\env\lib\site-packages\docx\oxml\text\run.py", line 252, in add_text
    for char in text:
TypeError: 'NoneType' object is not iterable
2025-03-17 15:15:20,793 - ERROR - Une erreur est survenue
Traceback (most recent call last):
  File "c:\Users\LENOVO\Desktop\Academy\main.py", line 444, in generer_word
    row_cells[j].text = text
  File "C:\Users\LENOVO\Desktop\Academy\env\lib\site-packages\docx\table.py", line 284, in text
    r.text = text
  File "C:\Users\LENOVO\Desktop\Academy\env\lib\site-packages\docx\oxml\text\run.py", line 129, in text
    _RunContentAppender.append_to_run_from_text(self, text)
  File "C:\Users\LENOVO\Desktop\Academy\env\lib\site-packages\docx\oxml\text\run.py", line 248, in append_to_run_from_text
    appender.add_text(text)
  File "C:\Users\LENOVO\Desktop\Academy\env\lib\site-packages\docx\oxml\text\run.py", line 252, in add_text
    for char in text:
TypeError: 'NoneType' object is not iterable
2025-03-17 15:15:20,826 - ERROR - Une erreur est survenue
Traceback (most recent call last):
  File "c:\Users\LENOVO\Desktop\Academy\main.py", line 444, in generer_word
    row_cells[j].text = text
  File "C:\Users\LENOVO\Desktop\Academy\env\lib\site-packages\docx\table.py", line 284, in text
    r.text = text
  File "C:\Users\LENOVO\Desktop\Academy\env\lib\site-packages\docx\oxml\text\run.py", line 129, in text
    _RunContentAppender.append_to_run_from_text(self, text)
  File "C:\Users\LENOVO\Desktop\Academy\env\lib\site-packages\docx\oxml\text\run.py", line 248, in append_to_run_from_text
    appender.add_text(text)
  File "C:\Users\LENOVO\Desktop\Academy\env\lib\site-packages\docx\oxml\text\run.py", line 252, in add_text
    for char in text:
TypeError: 'NoneType' object is not iterable
2025-03-17 15:15:20,860 - ERROR - Une erreur est survenue
Traceback (most recent call last):
  File "c:\Users\LENOVO\Desktop\Academy\main.py", line 444, in generer_word
    row_cells[j].text = text
  File "C:\Users\LENOVO\Desktop\Academy\env\lib\site-packages\docx\table.py", line 284, in text
    r.text = text
  File "C:\Users\LENOVO\Desktop\Academy\env\lib\site-packages\docx\oxml\text\run.py", line 129, in text
    _RunContentAppender.append_to_run_from_text(self, text)
  File "C:\Users\LENOVO\Desktop\Academy\env\lib\site-packages\docx\oxml\text\run.py", line 248, in append_to_run_from_text
    appender.add_text(text)
  File "C:\Users\LENOVO\Desktop\Academy\env\lib\site-packages\docx\oxml\text\run.py", line 252, in add_text
    for char in text:
TypeError: 'NoneType' object is not iterable
2025-03-17 15:15:20,879 - ERROR - Une erreur est survenue
Traceback (most recent call last):
  File "c:\Users\LENOVO\Desktop\Academy\main.py", line 444, in generer_word
    row_cells[j].text = text
  File "C:\Users\LENOVO\Desktop\Academy\env\lib\site-packages\docx\table.py", line 284, in text
    r.text = text
  File "C:\Users\LENOVO\Desktop\Academy\env\lib\site-packages\docx\oxml\text\run.py", line 129, in text
    _RunContentAppender.append_to_run_from_text(self, text)
  File "C:\Users\LENOVO\Desktop\Academy\env\lib\site-packages\docx\oxml\text\run.py", line 248, in append_to_run_from_text
    appender.add_text(text)
  File "C:\Users\LENOVO\Desktop\Academy\env\lib\site-packages\docx\oxml\text\run.py", line 252, in add_text
    for char in text:
TypeError: 'NoneType' object is not iterable
2025-03-17 15:15:20,910 - ERROR - Une erreur est survenue
Traceback (most recent call last):
  File "c:\Users\LENOVO\Desktop\Academy\main.py", line 444, in generer_word
    row_cells[j].text = text
  File "C:\Users\LENOVO\Desktop\Academy\env\lib\site-packages\docx\table.py", line 284, in text
    r.text = text
  File "C:\Users\LENOVO\Desktop\Academy\env\lib\site-packages\docx\oxml\text\run.py", line 129, in text
    _RunContentAppender.append_to_run_from_text(self, text)
  File "C:\Users\LENOVO\Desktop\Academy\env\lib\site-packages\docx\oxml\text\run.py", line 248, in append_to_run_from_text
    appender.add_text(text)
  File "C:\Users\LENOVO\Desktop\Academy\env\lib\site-packages\docx\oxml\text\run.py", line 252, in add_text
    for char in text:
TypeError: 'NoneType' object is not iterable
2025-03-17 15:15:20,941 - ERROR - Une erreur est survenue
Traceback (most recent call last):
  File "c:\Users\LENOVO\Desktop\Academy\main.py", line 444, in generer_word
    row_cells[j].text = text
  File "C:\Users\LENOVO\Desktop\Academy\env\lib\site-packages\docx\table.py", line 284, in text
    r.text = text
  File "C:\Users\LENOVO\Desktop\Academy\env\lib\site-packages\docx\oxml\text\run.py", line 129, in text
    _RunContentAppender.append_to_run_from_text(self, text)
  File "C:\Users\LENOVO\Desktop\Academy\env\lib\site-packages\docx\oxml\text\run.py", line 248, in append_to_run_from_text
    appender.add_text(text)
  File "C:\Users\LENOVO\Desktop\Academy\env\lib\site-packages\docx\oxml\text\run.py", line 252, in add_text
    for char in text:
TypeError: 'NoneType' object is not iterable
2025-03-17 15:15:20,973 - ERROR - Une erreur est survenue
Traceback (most recent call last):
  File "c:\Users\LENOVO\Desktop\Academy\main.py", line 444, in generer_word
    row_cells[j].text = text
  File "C:\Users\LENOVO\Desktop\Academy\env\lib\site-packages\docx\table.py", line 284, in text
    r.text = text
  File "C:\Users\LENOVO\Desktop\Academy\env\lib\site-packages\docx\oxml\text\run.py", line 129, in text
    _RunContentAppender.append_to_run_from_text(self, text)
  File "C:\Users\LENOVO\Desktop\Academy\env\lib\site-packages\docx\oxml\text\run.py", line 248, in append_to_run_from_text
    appender.add_text(text)
  File "C:\Users\LENOVO\Desktop\Academy\env\lib\site-packages\docx\oxml\text\run.py", line 252, in add_text
    for char in text:
TypeError: 'NoneType' object is not iterable
2025-03-17 15:15:21,002 - ERROR - Une erreur est survenue
Traceback (most recent call last):
  File "c:\Users\LENOVO\Desktop\Academy\main.py", line 444, in generer_word
    row_cells[j].text = text
  File "C:\Users\LENOVO\Desktop\Academy\env\lib\site-packages\docx\table.py", line 284, in text
    r.text = text
  File "C:\Users\LENOVO\Desktop\Academy\env\lib\site-packages\docx\oxml\text\run.py", line 129, in text
    _RunContentAppender.append_to_run_from_text(self, text)
  File "C:\Users\LENOVO\Desktop\Academy\env\lib\site-packages\docx\oxml\text\run.py", line 248, in append_to_run_from_text
    appender.add_text(text)
  File "C:\Users\LENOVO\Desktop\Academy\env\lib\site-packages\docx\oxml\text\run.py", line 252, in add_text
    for char in text:
TypeError: 'NoneType' object is not iterable
2025-03-17 15:15:21,285 - ERROR - Une erreur est survenue
Traceback (most recent call last):
  File "c:\Users\LENOVO\Desktop\Academy\main.py", line 444, in generer_word
    row_cells[j].text = text
  File "C:\Users\LENOVO\Desktop\Academy\env\lib\site-packages\docx\table.py", line 284, in text
    r.text = text
  File "C:\Users\LENOVO\Desktop\Academy\env\lib\site-packages\docx\oxml\text\run.py", line 129, in text
    _RunContentAppender.append_to_run_from_text(self, text)
  File "C:\Users\LENOVO\Desktop\Academy\env\lib\site-packages\docx\oxml\text\run.py", line 248, in append_to_run_from_text
    appender.add_text(text)
  File "C:\Users\LENOVO\Desktop\Academy\env\lib\site-packages\docx\oxml\text\run.py", line 252, in add_text
    for char in text:
TypeError: 'NoneType' object is not iterable
2025-03-17 15:15:21,423 - ERROR - Une erreur est survenue
Traceback (most recent call last):
  File "c:\Users\LENOVO\Desktop\Academy\main.py", line 444, in generer_word
    row_cells[j].text = text
  File "C:\Users\LENOVO\Desktop\Academy\env\lib\site-packages\docx\table.py", line 284, in text
    r.text = text
  File "C:\Users\LENOVO\Desktop\Academy\env\lib\site-packages\docx\oxml\text\run.py", line 129, in text
    _RunContentAppender.append_to_run_from_text(self, text)
  File "C:\Users\LENOVO\Desktop\Academy\env\lib\site-packages\docx\oxml\text\run.py", line 248, in append_to_run_from_text
    appender.add_text(text)
  File "C:\Users\LENOVO\Desktop\Academy\env\lib\site-packages\docx\oxml\text\run.py", line 252, in add_text
    for char in text:
TypeError: 'NoneType' object is not iterable
2025-03-17 15:15:21,578 - ERROR - Une erreur est survenue
Traceback (most recent call last):
  File "c:\Users\LENOVO\Desktop\Academy\main.py", line 444, in generer_word
    row_cells[j].text = text
  File "C:\Users\LENOVO\Desktop\Academy\env\lib\site-packages\docx\table.py", line 284, in text
    r.text = text
  File "C:\Users\LENOVO\Desktop\Academy\env\lib\site-packages\docx\oxml\text\run.py", line 129, in text
    _RunContentAppender.append_to_run_from_text(self, text)
  File "C:\Users\LENOVO\Desktop\Academy\env\lib\site-packages\docx\oxml\text\run.py", line 248, in append_to_run_from_text
    appender.add_text(text)
  File "C:\Users\LENOVO\Desktop\Academy\env\lib\site-packages\docx\oxml\text\run.py", line 252, in add_text
    for char in text:
TypeError: 'NoneType' object is not iterable
2025-03-17 15:15:21,814 - ERROR - Une erreur est survenue
Traceback (most recent call last):
  File "c:\Users\LENOVO\Desktop\Academy\main.py", line 444, in generer_word
    row_cells[j].text = text
  File "C:\Users\LENOVO\Desktop\Academy\env\lib\site-packages\docx\table.py", line 284, in text
    r.text = text
  File "C:\Users\LENOVO\Desktop\Academy\env\lib\site-packages\docx\oxml\text\run.py", line 129, in text
    _RunContentAppender.append_to_run_from_text(self, text)
  File "C:\Users\LENOVO\Desktop\Academy\env\lib\site-packages\docx\oxml\text\run.py", line 248, in append_to_run_from_text
    appender.add_text(text)
  File "C:\Users\LENOVO\Desktop\Academy\env\lib\site-packages\docx\oxml\text\run.py", line 252, in add_text
    for char in text:
TypeError: 'NoneType' object is not iterable
2025-03-17 15:15:22,255 - ERROR - Une erreur est survenue
Traceback (most recent call last):
  File "c:\Users\LENOVO\Desktop\Academy\main.py", line 444, in generer_word
    row_cells[j].text = text
  File "C:\Users\LENOVO\Desktop\Academy\env\lib\site-packages\docx\table.py", line 284, in text
    r.text = text
  File "C:\Users\LENOVO\Desktop\Academy\env\lib\site-packages\docx\oxml\text\run.py", line 129, in text
    _RunContentAppender.append_to_run_from_text(self, text)
  File "C:\Users\LENOVO\Desktop\Academy\env\lib\site-packages\docx\oxml\text\run.py", line 248, in append_to_run_from_text
    appender.add_text(text)
  File "C:\Users\LENOVO\Desktop\Academy\env\lib\site-packages\docx\oxml\text\run.py", line 252, in add_text
    for char in text:
TypeError: 'NoneType' object is not iterable
2025-03-17 15:15:22,297 - ERROR - Une erreur est survenue
Traceback (most recent call last):
  File "c:\Users\LENOVO\Desktop\Academy\main.py", line 444, in generer_word
    row_cells[j].text = text
  File "C:\Users\LENOVO\Desktop\Academy\env\lib\site-packages\docx\table.py", line 284, in text
    r.text = text
  File "C:\Users\LENOVO\Desktop\Academy\env\lib\site-packages\docx\oxml\text\run.py", line 129, in text
    _RunContentAppender.append_to_run_from_text(self, text)
  File "C:\Users\LENOVO\Desktop\Academy\env\lib\site-packages\docx\oxml\text\run.py", line 248, in append_to_run_from_text
    appender.add_text(text)
  File "C:\Users\LENOVO\Desktop\Academy\env\lib\site-packages\docx\oxml\text\run.py", line 252, in add_text
    for char in text:
TypeError: 'NoneType' object is not iterable
2025-03-17 15:15:23,776 - ERROR - Une erreur est survenue
Traceback (most recent call last):
  File "c:\Users\LENOVO\Desktop\Academy\main.py", line 444, in generer_word
    row_cells[j].text = text
  File "C:\Users\LENOVO\Desktop\Academy\env\lib\site-packages\docx\table.py", line 284, in text
    r.text = text
  File "C:\Users\LENOVO\Desktop\Academy\env\lib\site-packages\docx\oxml\text\run.py", line 129, in text
    _RunContentAppender.append_to_run_from_text(self, text)
  File "C:\Users\LENOVO\Desktop\Academy\env\lib\site-packages\docx\oxml\text\run.py", line 248, in append_to_run_from_text
    appender.add_text(text)
  File "C:\Users\LENOVO\Desktop\Academy\env\lib\site-packages\docx\oxml\text\run.py", line 252, in add_text
    for char in text:
TypeError: 'NoneType' object is not iterable
2025-03-17 15:15:23,934 - ERROR - Une erreur est survenue
Traceback (most recent call last):
  File "c:\Users\LENOVO\Desktop\Academy\main.py", line 444, in generer_word
    row_cells[j].text = text
  File "C:\Users\LENOVO\Desktop\Academy\env\lib\site-packages\docx\table.py", line 284, in text
    r.text = text
  File "C:\Users\LENOVO\Desktop\Academy\env\lib\site-packages\docx\oxml\text\run.py", line 129, in text
    _RunContentAppender.append_to_run_from_text(self, text)
  File "C:\Users\LENOVO\Desktop\Academy\env\lib\site-packages\docx\oxml\text\run.py", line 248, in append_to_run_from_text
    appender.add_text(text)
  File "C:\Users\LENOVO\Desktop\Academy\env\lib\site-packages\docx\oxml\text\run.py", line 252, in add_text
    for char in text:
TypeError: 'NoneType' object is not iterable
2025-03-17 15:15:24,705 - ERROR - Une erreur est survenue
Traceback (most recent call last):
  File "c:\Users\LENOVO\Desktop\Academy\main.py", line 444, in generer_word
    row_cells[j].text = text
  File "C:\Users\LENOVO\Desktop\Academy\env\lib\site-packages\docx\table.py", line 284, in text
    r.text = text
  File "C:\Users\LENOVO\Desktop\Academy\env\lib\site-packages\docx\oxml\text\run.py", line 129, in text
    _RunContentAppender.append_to_run_from_text(self, text)
  File "C:\Users\LENOVO\Desktop\Academy\env\lib\site-packages\docx\oxml\text\run.py", line 248, in append_to_run_from_text
    appender.add_text(text)
  File "C:\Users\LENOVO\Desktop\Academy\env\lib\site-packages\docx\oxml\text\run.py", line 252, in add_text
    for char in text:
TypeError: 'NoneType' object is not iterable
2025-03-17 15:15:24,729 - ERROR - Une erreur est survenue
Traceback (most recent call last):
  File "c:\Users\LENOVO\Desktop\Academy\main.py", line 444, in generer_word
    row_cells[j].text = text
  File "C:\Users\LENOVO\Desktop\Academy\env\lib\site-packages\docx\table.py", line 284, in text
    r.text = text
  File "C:\Users\LENOVO\Desktop\Academy\env\lib\site-packages\docx\oxml\text\run.py", line 129, in text
    _RunContentAppender.append_to_run_from_text(self, text)
  File "C:\Users\LENOVO\Desktop\Academy\env\lib\site-packages\docx\oxml\text\run.py", line 248, in append_to_run_from_text
    appender.add_text(text)
  File "C:\Users\LENOVO\Desktop\Academy\env\lib\site-packages\docx\oxml\text\run.py", line 252, in add_text
    for char in text:
TypeError: 'NoneType' object is not iterable
2025-03-17 15:15:26,456 - ERROR - Une erreur est survenue
Traceback (most recent call last):
  File "c:\Users\LENOVO\Desktop\Academy\main.py", line 444, in generer_word
    row_cells[j].text = text
  File "C:\Users\LENOVO\Desktop\Academy\env\lib\site-packages\docx\table.py", line 284, in text
    r.text = text
  File "C:\Users\LENOVO\Desktop\Academy\env\lib\site-packages\docx\oxml\text\run.py", line 129, in text
    _RunContentAppender.append_to_run_from_text(self, text)
  File "C:\Users\LENOVO\Desktop\Academy\env\lib\site-packages\docx\oxml\text\run.py", line 248, in append_to_run_from_text
    appender.add_text(text)
  File "C:\Users\LENOVO\Desktop\Academy\env\lib\site-packages\docx\oxml\text\run.py", line 252, in add_text
    for char in text:
TypeError: 'NoneType' object is not iterable
2025-03-17 15:19:57,288 - ERROR - Une erreur est survenue
Traceback (most recent call last):
  File "c:\Users\LENOVO\Desktop\Academy\main.py", line 444, in generer_word
    row_cells[j].text = text
  File "C:\Users\LENOVO\Desktop\Academy\env\lib\site-packages\docx\table.py", line 284, in text
    r.text = text
  File "C:\Users\LENOVO\Desktop\Academy\env\lib\site-packages\docx\oxml\text\run.py", line 129, in text
    _RunContentAppender.append_to_run_from_text(self, text)
  File "C:\Users\LENOVO\Desktop\Academy\env\lib\site-packages\docx\oxml\text\run.py", line 248, in append_to_run_from_text
    appender.add_text(text)
  File "C:\Users\LENOVO\Desktop\Academy\env\lib\site-packages\docx\oxml\text\run.py", line 252, in add_text
    for char in text:
TypeError: 'NoneType' object is not iterable
2025-03-17 15:19:57,350 - ERROR - Une erreur est survenue
Traceback (most recent call last):
  File "c:\Users\LENOVO\Desktop\Academy\main.py", line 444, in generer_word
    row_cells[j].text = text
  File "C:\Users\LENOVO\Desktop\Academy\env\lib\site-packages\docx\table.py", line 284, in text
    r.text = text
  File "C:\Users\LENOVO\Desktop\Academy\env\lib\site-packages\docx\oxml\text\run.py", line 129, in text
    _RunContentAppender.append_to_run_from_text(self, text)
  File "C:\Users\LENOVO\Desktop\Academy\env\lib\site-packages\docx\oxml\text\run.py", line 248, in append_to_run_from_text
    appender.add_text(text)
  File "C:\Users\LENOVO\Desktop\Academy\env\lib\site-packages\docx\oxml\text\run.py", line 252, in add_text
    for char in text:
TypeError: 'NoneType' object is not iterable
2025-03-17 15:19:57,366 - ERROR - Une erreur est survenue
Traceback (most recent call last):
  File "c:\Users\LENOVO\Desktop\Academy\main.py", line 444, in generer_word
    row_cells[j].text = text
  File "C:\Users\LENOVO\Desktop\Academy\env\lib\site-packages\docx\table.py", line 284, in text
    r.text = text
  File "C:\Users\LENOVO\Desktop\Academy\env\lib\site-packages\docx\oxml\text\run.py", line 129, in text
    _RunContentAppender.append_to_run_from_text(self, text)
  File "C:\Users\LENOVO\Desktop\Academy\env\lib\site-packages\docx\oxml\text\run.py", line 248, in append_to_run_from_text
    appender.add_text(text)
  File "C:\Users\LENOVO\Desktop\Academy\env\lib\site-packages\docx\oxml\text\run.py", line 252, in add_text
    for char in text:
TypeError: 'NoneType' object is not iterable
2025-03-17 15:19:57,429 - ERROR - Une erreur est survenue
Traceback (most recent call last):
  File "c:\Users\LENOVO\Desktop\Academy\main.py", line 444, in generer_word
    row_cells[j].text = text
  File "C:\Users\LENOVO\Desktop\Academy\env\lib\site-packages\docx\table.py", line 284, in text
    r.text = text
  File "C:\Users\LENOVO\Desktop\Academy\env\lib\site-packages\docx\oxml\text\run.py", line 129, in text
    _RunContentAppender.append_to_run_from_text(self, text)
  File "C:\Users\LENOVO\Desktop\Academy\env\lib\site-packages\docx\oxml\text\run.py", line 248, in append_to_run_from_text
    appender.add_text(text)
  File "C:\Users\LENOVO\Desktop\Academy\env\lib\site-packages\docx\oxml\text\run.py", line 252, in add_text
    for char in text:
TypeError: 'NoneType' object is not iterable
2025-03-17 15:19:58,795 - ERROR - Une erreur est survenue
Traceback (most recent call last):
  File "c:\Users\LENOVO\Desktop\Academy\main.py", line 444, in generer_word
    row_cells[j].text = text
  File "C:\Users\LENOVO\Desktop\Academy\env\lib\site-packages\docx\table.py", line 284, in text
    r.text = text
  File "C:\Users\LENOVO\Desktop\Academy\env\lib\site-packages\docx\oxml\text\run.py", line 129, in text
    _RunContentAppender.append_to_run_from_text(self, text)
  File "C:\Users\LENOVO\Desktop\Academy\env\lib\site-packages\docx\oxml\text\run.py", line 248, in append_to_run_from_text
    appender.add_text(text)
  File "C:\Users\LENOVO\Desktop\Academy\env\lib\site-packages\docx\oxml\text\run.py", line 252, in add_text
    for char in text:
TypeError: 'NoneType' object is not iterable
2025-03-17 15:19:58,842 - ERROR - Une erreur est survenue
Traceback (most recent call last):
  File "c:\Users\LENOVO\Desktop\Academy\main.py", line 444, in generer_word
    row_cells[j].text = text
  File "C:\Users\LENOVO\Desktop\Academy\env\lib\site-packages\docx\table.py", line 284, in text
    r.text = text
  File "C:\Users\LENOVO\Desktop\Academy\env\lib\site-packages\docx\oxml\text\run.py", line 129, in text
    _RunContentAppender.append_to_run_from_text(self, text)
  File "C:\Users\LENOVO\Desktop\Academy\env\lib\site-packages\docx\oxml\text\run.py", line 248, in append_to_run_from_text
    appender.add_text(text)
  File "C:\Users\LENOVO\Desktop\Academy\env\lib\site-packages\docx\oxml\text\run.py", line 252, in add_text
    for char in text:
TypeError: 'NoneType' object is not iterable
2025-03-17 15:19:58,874 - ERROR - Une erreur est survenue
Traceback (most recent call last):
  File "c:\Users\LENOVO\Desktop\Academy\main.py", line 444, in generer_word
    row_cells[j].text = text
  File "C:\Users\LENOVO\Desktop\Academy\env\lib\site-packages\docx\table.py", line 284, in text
    r.text = text
  File "C:\Users\LENOVO\Desktop\Academy\env\lib\site-packages\docx\oxml\text\run.py", line 129, in text
    _RunContentAppender.append_to_run_from_text(self, text)
  File "C:\Users\LENOVO\Desktop\Academy\env\lib\site-packages\docx\oxml\text\run.py", line 248, in append_to_run_from_text
    appender.add_text(text)
  File "C:\Users\LENOVO\Desktop\Academy\env\lib\site-packages\docx\oxml\text\run.py", line 252, in add_text
    for char in text:
TypeError: 'NoneType' object is not iterable
2025-03-17 15:19:58,921 - ERROR - Une erreur est survenue
Traceback (most recent call last):
  File "c:\Users\LENOVO\Desktop\Academy\main.py", line 444, in generer_word
    row_cells[j].text = text
  File "C:\Users\LENOVO\Desktop\Academy\env\lib\site-packages\docx\table.py", line 284, in text
    r.text = text
  File "C:\Users\LENOVO\Desktop\Academy\env\lib\site-packages\docx\oxml\text\run.py", line 129, in text
    _RunContentAppender.append_to_run_from_text(self, text)
  File "C:\Users\LENOVO\Desktop\Academy\env\lib\site-packages\docx\oxml\text\run.py", line 248, in append_to_run_from_text
    appender.add_text(text)
  File "C:\Users\LENOVO\Desktop\Academy\env\lib\site-packages\docx\oxml\text\run.py", line 252, in add_text
    for char in text:
TypeError: 'NoneType' object is not iterable
2025-03-17 15:19:58,968 - ERROR - Une erreur est survenue
Traceback (most recent call last):
  File "c:\Users\LENOVO\Desktop\Academy\main.py", line 444, in generer_word
    row_cells[j].text = text
  File "C:\Users\LENOVO\Desktop\Academy\env\lib\site-packages\docx\table.py", line 284, in text
    r.text = text
  File "C:\Users\LENOVO\Desktop\Academy\env\lib\site-packages\docx\oxml\text\run.py", line 129, in text
    _RunContentAppender.append_to_run_from_text(self, text)
  File "C:\Users\LENOVO\Desktop\Academy\env\lib\site-packages\docx\oxml\text\run.py", line 248, in append_to_run_from_text
    appender.add_text(text)
  File "C:\Users\LENOVO\Desktop\Academy\env\lib\site-packages\docx\oxml\text\run.py", line 252, in add_text
    for char in text:
TypeError: 'NoneType' object is not iterable
2025-03-17 15:19:59,031 - ERROR - Une erreur est survenue
Traceback (most recent call last):
  File "c:\Users\LENOVO\Desktop\Academy\main.py", line 444, in generer_word
    row_cells[j].text = text
  File "C:\Users\LENOVO\Desktop\Academy\env\lib\site-packages\docx\table.py", line 284, in text
    r.text = text
  File "C:\Users\LENOVO\Desktop\Academy\env\lib\site-packages\docx\oxml\text\run.py", line 129, in text
    _RunContentAppender.append_to_run_from_text(self, text)
  File "C:\Users\LENOVO\Desktop\Academy\env\lib\site-packages\docx\oxml\text\run.py", line 248, in append_to_run_from_text
    appender.add_text(text)
  File "C:\Users\LENOVO\Desktop\Academy\env\lib\site-packages\docx\oxml\text\run.py", line 252, in add_text
    for char in text:
TypeError: 'NoneType' object is not iterable
2025-03-17 15:19:59,094 - ERROR - Une erreur est survenue
Traceback (most recent call last):
  File "c:\Users\LENOVO\Desktop\Academy\main.py", line 444, in generer_word
    row_cells[j].text = text
  File "C:\Users\LENOVO\Desktop\Academy\env\lib\site-packages\docx\table.py", line 284, in text
    r.text = text
  File "C:\Users\LENOVO\Desktop\Academy\env\lib\site-packages\docx\oxml\text\run.py", line 129, in text
    _RunContentAppender.append_to_run_from_text(self, text)
  File "C:\Users\LENOVO\Desktop\Academy\env\lib\site-packages\docx\oxml\text\run.py", line 248, in append_to_run_from_text
    appender.add_text(text)
  File "C:\Users\LENOVO\Desktop\Academy\env\lib\site-packages\docx\oxml\text\run.py", line 252, in add_text
    for char in text:
TypeError: 'NoneType' object is not iterable
2025-03-17 15:19:59,140 - ERROR - Une erreur est survenue
Traceback (most recent call last):
  File "c:\Users\LENOVO\Desktop\Academy\main.py", line 444, in generer_word
    row_cells[j].text = text
  File "C:\Users\LENOVO\Desktop\Academy\env\lib\site-packages\docx\table.py", line 284, in text
    r.text = text
  File "C:\Users\LENOVO\Desktop\Academy\env\lib\site-packages\docx\oxml\text\run.py", line 129, in text
    _RunContentAppender.append_to_run_from_text(self, text)
  File "C:\Users\LENOVO\Desktop\Academy\env\lib\site-packages\docx\oxml\text\run.py", line 248, in append_to_run_from_text
    appender.add_text(text)
  File "C:\Users\LENOVO\Desktop\Academy\env\lib\site-packages\docx\oxml\text\run.py", line 252, in add_text
    for char in text:
TypeError: 'NoneType' object is not iterable
2025-03-17 15:19:59,172 - ERROR - Une erreur est survenue
Traceback (most recent call last):
  File "c:\Users\LENOVO\Desktop\Academy\main.py", line 444, in generer_word
    row_cells[j].text = text
  File "C:\Users\LENOVO\Desktop\Academy\env\lib\site-packages\docx\table.py", line 284, in text
    r.text = text
  File "C:\Users\LENOVO\Desktop\Academy\env\lib\site-packages\docx\oxml\text\run.py", line 129, in text
    _RunContentAppender.append_to_run_from_text(self, text)
  File "C:\Users\LENOVO\Desktop\Academy\env\lib\site-packages\docx\oxml\text\run.py", line 248, in append_to_run_from_text
    appender.add_text(text)
  File "C:\Users\LENOVO\Desktop\Academy\env\lib\site-packages\docx\oxml\text\run.py", line 252, in add_text
    for char in text:
TypeError: 'NoneType' object is not iterable
2025-03-17 15:19:59,203 - ERROR - Une erreur est survenue
Traceback (most recent call last):
  File "c:\Users\LENOVO\Desktop\Academy\main.py", line 444, in generer_word
    row_cells[j].text = text
  File "C:\Users\LENOVO\Desktop\Academy\env\lib\site-packages\docx\table.py", line 284, in text
    r.text = text
  File "C:\Users\LENOVO\Desktop\Academy\env\lib\site-packages\docx\oxml\text\run.py", line 129, in text
    _RunContentAppender.append_to_run_from_text(self, text)
  File "C:\Users\LENOVO\Desktop\Academy\env\lib\site-packages\docx\oxml\text\run.py", line 248, in append_to_run_from_text
    appender.add_text(text)
  File "C:\Users\LENOVO\Desktop\Academy\env\lib\site-packages\docx\oxml\text\run.py", line 252, in add_text
    for char in text:
TypeError: 'NoneType' object is not iterable
2025-03-17 15:19:59,235 - ERROR - Une erreur est survenue
Traceback (most recent call last):
  File "c:\Users\LENOVO\Desktop\Academy\main.py", line 444, in generer_word
    row_cells[j].text = text
  File "C:\Users\LENOVO\Desktop\Academy\env\lib\site-packages\docx\table.py", line 284, in text
    r.text = text
  File "C:\Users\LENOVO\Desktop\Academy\env\lib\site-packages\docx\oxml\text\run.py", line 129, in text
    _RunContentAppender.append_to_run_from_text(self, text)
  File "C:\Users\LENOVO\Desktop\Academy\env\lib\site-packages\docx\oxml\text\run.py", line 248, in append_to_run_from_text
    appender.add_text(text)
  File "C:\Users\LENOVO\Desktop\Academy\env\lib\site-packages\docx\oxml\text\run.py", line 252, in add_text
    for char in text:
TypeError: 'NoneType' object is not iterable
2025-03-17 15:19:59,265 - ERROR - Une erreur est survenue
Traceback (most recent call last):
  File "c:\Users\LENOVO\Desktop\Academy\main.py", line 444, in generer_word
    row_cells[j].text = text
  File "C:\Users\LENOVO\Desktop\Academy\env\lib\site-packages\docx\table.py", line 284, in text
    r.text = text
  File "C:\Users\LENOVO\Desktop\Academy\env\lib\site-packages\docx\oxml\text\run.py", line 129, in text
    _RunContentAppender.append_to_run_from_text(self, text)
  File "C:\Users\LENOVO\Desktop\Academy\env\lib\site-packages\docx\oxml\text\run.py", line 248, in append_to_run_from_text
    appender.add_text(text)
  File "C:\Users\LENOVO\Desktop\Academy\env\lib\site-packages\docx\oxml\text\run.py", line 252, in add_text
    for char in text:
TypeError: 'NoneType' object is not iterable
2025-03-17 15:19:59,266 - ERROR - Une erreur est survenue
Traceback (most recent call last):
  File "c:\Users\LENOVO\Desktop\Academy\main.py", line 444, in generer_word
    row_cells[j].text = text
  File "C:\Users\LENOVO\Desktop\Academy\env\lib\site-packages\docx\table.py", line 284, in text
    r.text = text
  File "C:\Users\LENOVO\Desktop\Academy\env\lib\site-packages\docx\oxml\text\run.py", line 129, in text
    _RunContentAppender.append_to_run_from_text(self, text)
  File "C:\Users\LENOVO\Desktop\Academy\env\lib\site-packages\docx\oxml\text\run.py", line 248, in append_to_run_from_text
    appender.add_text(text)
  File "C:\Users\LENOVO\Desktop\Academy\env\lib\site-packages\docx\oxml\text\run.py", line 252, in add_text
    for char in text:
TypeError: 'NoneType' object is not iterable
2025-03-17 15:19:59,282 - ERROR - Une erreur est survenue
Traceback (most recent call last):
  File "c:\Users\LENOVO\Desktop\Academy\main.py", line 444, in generer_word
    row_cells[j].text = text
  File "C:\Users\LENOVO\Desktop\Academy\env\lib\site-packages\docx\table.py", line 284, in text
    r.text = text
  File "C:\Users\LENOVO\Desktop\Academy\env\lib\site-packages\docx\oxml\text\run.py", line 129, in text
    _RunContentAppender.append_to_run_from_text(self, text)
  File "C:\Users\LENOVO\Desktop\Academy\env\lib\site-packages\docx\oxml\text\run.py", line 248, in append_to_run_from_text
    appender.add_text(text)
  File "C:\Users\LENOVO\Desktop\Academy\env\lib\site-packages\docx\oxml\text\run.py", line 252, in add_text
    for char in text:
TypeError: 'NoneType' object is not iterable
2025-03-17 15:19:59,313 - ERROR - Une erreur est survenue
Traceback (most recent call last):
  File "c:\Users\LENOVO\Desktop\Academy\main.py", line 444, in generer_word
    row_cells[j].text = text
  File "C:\Users\LENOVO\Desktop\Academy\env\lib\site-packages\docx\table.py", line 284, in text
    r.text = text
  File "C:\Users\LENOVO\Desktop\Academy\env\lib\site-packages\docx\oxml\text\run.py", line 129, in text
    _RunContentAppender.append_to_run_from_text(self, text)
  File "C:\Users\LENOVO\Desktop\Academy\env\lib\site-packages\docx\oxml\text\run.py", line 248, in append_to_run_from_text
    appender.add_text(text)
  File "C:\Users\LENOVO\Desktop\Academy\env\lib\site-packages\docx\oxml\text\run.py", line 252, in add_text
    for char in text:
TypeError: 'NoneType' object is not iterable
2025-03-17 15:19:59,344 - ERROR - Une erreur est survenue
Traceback (most recent call last):
  File "c:\Users\LENOVO\Desktop\Academy\main.py", line 444, in generer_word
    row_cells[j].text = text
  File "C:\Users\LENOVO\Desktop\Academy\env\lib\site-packages\docx\table.py", line 284, in text
    r.text = text
  File "C:\Users\LENOVO\Desktop\Academy\env\lib\site-packages\docx\oxml\text\run.py", line 129, in text
    _RunContentAppender.append_to_run_from_text(self, text)
  File "C:\Users\LENOVO\Desktop\Academy\env\lib\site-packages\docx\oxml\text\run.py", line 248, in append_to_run_from_text
    appender.add_text(text)
  File "C:\Users\LENOVO\Desktop\Academy\env\lib\site-packages\docx\oxml\text\run.py", line 252, in add_text
    for char in text:
TypeError: 'NoneType' object is not iterable
2025-03-17 15:19:59,376 - ERROR - Une erreur est survenue
Traceback (most recent call last):
  File "c:\Users\LENOVO\Desktop\Academy\main.py", line 444, in generer_word
    row_cells[j].text = text
  File "C:\Users\LENOVO\Desktop\Academy\env\lib\site-packages\docx\table.py", line 284, in text
    r.text = text
  File "C:\Users\LENOVO\Desktop\Academy\env\lib\site-packages\docx\oxml\text\run.py", line 129, in text
    _RunContentAppender.append_to_run_from_text(self, text)
  File "C:\Users\LENOVO\Desktop\Academy\env\lib\site-packages\docx\oxml\text\run.py", line 248, in append_to_run_from_text
    appender.add_text(text)
  File "C:\Users\LENOVO\Desktop\Academy\env\lib\site-packages\docx\oxml\text\run.py", line 252, in add_text
    for char in text:
TypeError: 'NoneType' object is not iterable
2025-03-17 15:19:59,392 - ERROR - Une erreur est survenue
Traceback (most recent call last):
  File "c:\Users\LENOVO\Desktop\Academy\main.py", line 444, in generer_word
    row_cells[j].text = text
  File "C:\Users\LENOVO\Desktop\Academy\env\lib\site-packages\docx\table.py", line 284, in text
    r.text = text
  File "C:\Users\LENOVO\Desktop\Academy\env\lib\site-packages\docx\oxml\text\run.py", line 129, in text
    _RunContentAppender.append_to_run_from_text(self, text)
  File "C:\Users\LENOVO\Desktop\Academy\env\lib\site-packages\docx\oxml\text\run.py", line 248, in append_to_run_from_text
    appender.add_text(text)
  File "C:\Users\LENOVO\Desktop\Academy\env\lib\site-packages\docx\oxml\text\run.py", line 252, in add_text
    for char in text:
TypeError: 'NoneType' object is not iterable
2025-03-17 15:19:59,423 - ERROR - Une erreur est survenue
Traceback (most recent call last):
  File "c:\Users\LENOVO\Desktop\Academy\main.py", line 444, in generer_word
    row_cells[j].text = text
  File "C:\Users\LENOVO\Desktop\Academy\env\lib\site-packages\docx\table.py", line 284, in text
    r.text = text
  File "C:\Users\LENOVO\Desktop\Academy\env\lib\site-packages\docx\oxml\text\run.py", line 129, in text
    _RunContentAppender.append_to_run_from_text(self, text)
  File "C:\Users\LENOVO\Desktop\Academy\env\lib\site-packages\docx\oxml\text\run.py", line 248, in append_to_run_from_text
    appender.add_text(text)
  File "C:\Users\LENOVO\Desktop\Academy\env\lib\site-packages\docx\oxml\text\run.py", line 252, in add_text
    for char in text:
TypeError: 'NoneType' object is not iterable
2025-03-17 15:19:59,454 - ERROR - Une erreur est survenue
Traceback (most recent call last):
  File "c:\Users\LENOVO\Desktop\Academy\main.py", line 444, in generer_word
    row_cells[j].text = text
  File "C:\Users\LENOVO\Desktop\Academy\env\lib\site-packages\docx\table.py", line 284, in text
    r.text = text
  File "C:\Users\LENOVO\Desktop\Academy\env\lib\site-packages\docx\oxml\text\run.py", line 129, in text
    _RunContentAppender.append_to_run_from_text(self, text)
  File "C:\Users\LENOVO\Desktop\Academy\env\lib\site-packages\docx\oxml\text\run.py", line 248, in append_to_run_from_text
    appender.add_text(text)
  File "C:\Users\LENOVO\Desktop\Academy\env\lib\site-packages\docx\oxml\text\run.py", line 252, in add_text
    for char in text:
TypeError: 'NoneType' object is not iterable
2025-03-17 15:19:59,517 - ERROR - Une erreur est survenue
Traceback (most recent call last):
  File "c:\Users\LENOVO\Desktop\Academy\main.py", line 444, in generer_word
    row_cells[j].text = text
  File "C:\Users\LENOVO\Desktop\Academy\env\lib\site-packages\docx\table.py", line 284, in text
    r.text = text
  File "C:\Users\LENOVO\Desktop\Academy\env\lib\site-packages\docx\oxml\text\run.py", line 129, in text
    _RunContentAppender.append_to_run_from_text(self, text)
  File "C:\Users\LENOVO\Desktop\Academy\env\lib\site-packages\docx\oxml\text\run.py", line 248, in append_to_run_from_text
    appender.add_text(text)
  File "C:\Users\LENOVO\Desktop\Academy\env\lib\site-packages\docx\oxml\text\run.py", line 252, in add_text
    for char in text:
TypeError: 'NoneType' object is not iterable
2025-03-17 15:19:59,549 - ERROR - Une erreur est survenue
Traceback (most recent call last):
  File "c:\Users\LENOVO\Desktop\Academy\main.py", line 444, in generer_word
    row_cells[j].text = text
  File "C:\Users\LENOVO\Desktop\Academy\env\lib\site-packages\docx\table.py", line 284, in text
    r.text = text
  File "C:\Users\LENOVO\Desktop\Academy\env\lib\site-packages\docx\oxml\text\run.py", line 129, in text
    _RunContentAppender.append_to_run_from_text(self, text)
  File "C:\Users\LENOVO\Desktop\Academy\env\lib\site-packages\docx\oxml\text\run.py", line 248, in append_to_run_from_text
    appender.add_text(text)
  File "C:\Users\LENOVO\Desktop\Academy\env\lib\site-packages\docx\oxml\text\run.py", line 252, in add_text
    for char in text:
TypeError: 'NoneType' object is not iterable
2025-03-17 15:19:59,612 - ERROR - Une erreur est survenue
Traceback (most recent call last):
  File "c:\Users\LENOVO\Desktop\Academy\main.py", line 444, in generer_word
    row_cells[j].text = text
  File "C:\Users\LENOVO\Desktop\Academy\env\lib\site-packages\docx\table.py", line 284, in text
    r.text = text
  File "C:\Users\LENOVO\Desktop\Academy\env\lib\site-packages\docx\oxml\text\run.py", line 129, in text
    _RunContentAppender.append_to_run_from_text(self, text)
  File "C:\Users\LENOVO\Desktop\Academy\env\lib\site-packages\docx\oxml\text\run.py", line 248, in append_to_run_from_text
    appender.add_text(text)
  File "C:\Users\LENOVO\Desktop\Academy\env\lib\site-packages\docx\oxml\text\run.py", line 252, in add_text
    for char in text:
TypeError: 'NoneType' object is not iterable
2025-03-17 15:19:59,643 - ERROR - Une erreur est survenue
Traceback (most recent call last):
  File "c:\Users\LENOVO\Desktop\Academy\main.py", line 444, in generer_word
    row_cells[j].text = text
  File "C:\Users\LENOVO\Desktop\Academy\env\lib\site-packages\docx\table.py", line 284, in text
    r.text = text
  File "C:\Users\LENOVO\Desktop\Academy\env\lib\site-packages\docx\oxml\text\run.py", line 129, in text
    _RunContentAppender.append_to_run_from_text(self, text)
  File "C:\Users\LENOVO\Desktop\Academy\env\lib\site-packages\docx\oxml\text\run.py", line 248, in append_to_run_from_text
    appender.add_text(text)
  File "C:\Users\LENOVO\Desktop\Academy\env\lib\site-packages\docx\oxml\text\run.py", line 252, in add_text
    for char in text:
TypeError: 'NoneType' object is not iterable
2025-03-17 15:19:59,675 - ERROR - Une erreur est survenue
Traceback (most recent call last):
  File "c:\Users\LENOVO\Desktop\Academy\main.py", line 444, in generer_word
    row_cells[j].text = text
  File "C:\Users\LENOVO\Desktop\Academy\env\lib\site-packages\docx\table.py", line 284, in text
    r.text = text
  File "C:\Users\LENOVO\Desktop\Academy\env\lib\site-packages\docx\oxml\text\run.py", line 129, in text
    _RunContentAppender.append_to_run_from_text(self, text)
  File "C:\Users\LENOVO\Desktop\Academy\env\lib\site-packages\docx\oxml\text\run.py", line 248, in append_to_run_from_text
    appender.add_text(text)
  File "C:\Users\LENOVO\Desktop\Academy\env\lib\site-packages\docx\oxml\text\run.py", line 252, in add_text
    for char in text:
TypeError: 'NoneType' object is not iterable
2025-03-17 15:19:59,706 - ERROR - Une erreur est survenue
Traceback (most recent call last):
  File "c:\Users\LENOVO\Desktop\Academy\main.py", line 444, in generer_word
    row_cells[j].text = text
  File "C:\Users\LENOVO\Desktop\Academy\env\lib\site-packages\docx\table.py", line 284, in text
    r.text = text
  File "C:\Users\LENOVO\Desktop\Academy\env\lib\site-packages\docx\oxml\text\run.py", line 129, in text
    _RunContentAppender.append_to_run_from_text(self, text)
  File "C:\Users\LENOVO\Desktop\Academy\env\lib\site-packages\docx\oxml\text\run.py", line 248, in append_to_run_from_text
    appender.add_text(text)
  File "C:\Users\LENOVO\Desktop\Academy\env\lib\site-packages\docx\oxml\text\run.py", line 252, in add_text
    for char in text:
TypeError: 'NoneType' object is not iterable
2025-03-17 15:19:59,722 - ERROR - Une erreur est survenue
Traceback (most recent call last):
  File "c:\Users\LENOVO\Desktop\Academy\main.py", line 444, in generer_word
    row_cells[j].text = text
  File "C:\Users\LENOVO\Desktop\Academy\env\lib\site-packages\docx\table.py", line 284, in text
    r.text = text
  File "C:\Users\LENOVO\Desktop\Academy\env\lib\site-packages\docx\oxml\text\run.py", line 129, in text
    _RunContentAppender.append_to_run_from_text(self, text)
  File "C:\Users\LENOVO\Desktop\Academy\env\lib\site-packages\docx\oxml\text\run.py", line 248, in append_to_run_from_text
    appender.add_text(text)
  File "C:\Users\LENOVO\Desktop\Academy\env\lib\site-packages\docx\oxml\text\run.py", line 252, in add_text
    for char in text:
TypeError: 'NoneType' object is not iterable
2025-03-17 15:19:59,753 - ERROR - Une erreur est survenue
Traceback (most recent call last):
  File "c:\Users\LENOVO\Desktop\Academy\main.py", line 444, in generer_word
    row_cells[j].text = text
  File "C:\Users\LENOVO\Desktop\Academy\env\lib\site-packages\docx\table.py", line 284, in text
    r.text = text
  File "C:\Users\LENOVO\Desktop\Academy\env\lib\site-packages\docx\oxml\text\run.py", line 129, in text
    _RunContentAppender.append_to_run_from_text(self, text)
  File "C:\Users\LENOVO\Desktop\Academy\env\lib\site-packages\docx\oxml\text\run.py", line 248, in append_to_run_from_text
    appender.add_text(text)
  File "C:\Users\LENOVO\Desktop\Academy\env\lib\site-packages\docx\oxml\text\run.py", line 252, in add_text
    for char in text:
TypeError: 'NoneType' object is not iterable
2025-03-17 15:19:59,785 - ERROR - Une erreur est survenue
Traceback (most recent call last):
  File "c:\Users\LENOVO\Desktop\Academy\main.py", line 444, in generer_word
    row_cells[j].text = text
  File "C:\Users\LENOVO\Desktop\Academy\env\lib\site-packages\docx\table.py", line 284, in text
    r.text = text
  File "C:\Users\LENOVO\Desktop\Academy\env\lib\site-packages\docx\oxml\text\run.py", line 129, in text
    _RunContentAppender.append_to_run_from_text(self, text)
  File "C:\Users\LENOVO\Desktop\Academy\env\lib\site-packages\docx\oxml\text\run.py", line 248, in append_to_run_from_text
    appender.add_text(text)
  File "C:\Users\LENOVO\Desktop\Academy\env\lib\site-packages\docx\oxml\text\run.py", line 252, in add_text
    for char in text:
TypeError: 'NoneType' object is not iterable
2025-03-17 15:19:59,816 - ERROR - Une erreur est survenue
Traceback (most recent call last):
  File "c:\Users\LENOVO\Desktop\Academy\main.py", line 444, in generer_word
    row_cells[j].text = text
  File "C:\Users\LENOVO\Desktop\Academy\env\lib\site-packages\docx\table.py", line 284, in text
    r.text = text
  File "C:\Users\LENOVO\Desktop\Academy\env\lib\site-packages\docx\oxml\text\run.py", line 129, in text
    _RunContentAppender.append_to_run_from_text(self, text)
  File "C:\Users\LENOVO\Desktop\Academy\env\lib\site-packages\docx\oxml\text\run.py", line 248, in append_to_run_from_text
    appender.add_text(text)
  File "C:\Users\LENOVO\Desktop\Academy\env\lib\site-packages\docx\oxml\text\run.py", line 252, in add_text
    for char in text:
TypeError: 'NoneType' object is not iterable
2025-03-17 15:19:59,847 - ERROR - Une erreur est survenue
Traceback (most recent call last):
  File "c:\Users\LENOVO\Desktop\Academy\main.py", line 444, in generer_word
    row_cells[j].text = text
  File "C:\Users\LENOVO\Desktop\Academy\env\lib\site-packages\docx\table.py", line 284, in text
    r.text = text
  File "C:\Users\LENOVO\Desktop\Academy\env\lib\site-packages\docx\oxml\text\run.py", line 129, in text
    _RunContentAppender.append_to_run_from_text(self, text)
  File "C:\Users\LENOVO\Desktop\Academy\env\lib\site-packages\docx\oxml\text\run.py", line 248, in append_to_run_from_text
    appender.add_text(text)
  File "C:\Users\LENOVO\Desktop\Academy\env\lib\site-packages\docx\oxml\text\run.py", line 252, in add_text
    for char in text:
TypeError: 'NoneType' object is not iterable
2025-03-17 15:19:59,847 - ERROR - Une erreur est survenue
Traceback (most recent call last):
  File "c:\Users\LENOVO\Desktop\Academy\main.py", line 444, in generer_word
    row_cells[j].text = text
  File "C:\Users\LENOVO\Desktop\Academy\env\lib\site-packages\docx\table.py", line 284, in text
    r.text = text
  File "C:\Users\LENOVO\Desktop\Academy\env\lib\site-packages\docx\oxml\text\run.py", line 129, in text
    _RunContentAppender.append_to_run_from_text(self, text)
  File "C:\Users\LENOVO\Desktop\Academy\env\lib\site-packages\docx\oxml\text\run.py", line 248, in append_to_run_from_text
    appender.add_text(text)
  File "C:\Users\LENOVO\Desktop\Academy\env\lib\site-packages\docx\oxml\text\run.py", line 252, in add_text
    for char in text:
TypeError: 'NoneType' object is not iterable
2025-03-17 15:19:59,867 - ERROR - Une erreur est survenue
Traceback (most recent call last):
  File "c:\Users\LENOVO\Desktop\Academy\main.py", line 444, in generer_word
    row_cells[j].text = text
  File "C:\Users\LENOVO\Desktop\Academy\env\lib\site-packages\docx\table.py", line 284, in text
    r.text = text
  File "C:\Users\LENOVO\Desktop\Academy\env\lib\site-packages\docx\oxml\text\run.py", line 129, in text
    _RunContentAppender.append_to_run_from_text(self, text)
  File "C:\Users\LENOVO\Desktop\Academy\env\lib\site-packages\docx\oxml\text\run.py", line 248, in append_to_run_from_text
    appender.add_text(text)
  File "C:\Users\LENOVO\Desktop\Academy\env\lib\site-packages\docx\oxml\text\run.py", line 252, in add_text
    for char in text:
TypeError: 'NoneType' object is not iterable
2025-03-17 15:19:59,895 - ERROR - Une erreur est survenue
Traceback (most recent call last):
  File "c:\Users\LENOVO\Desktop\Academy\main.py", line 444, in generer_word
    row_cells[j].text = text
  File "C:\Users\LENOVO\Desktop\Academy\env\lib\site-packages\docx\table.py", line 284, in text
    r.text = text
  File "C:\Users\LENOVO\Desktop\Academy\env\lib\site-packages\docx\oxml\text\run.py", line 129, in text
    _RunContentAppender.append_to_run_from_text(self, text)
  File "C:\Users\LENOVO\Desktop\Academy\env\lib\site-packages\docx\oxml\text\run.py", line 248, in append_to_run_from_text
    appender.add_text(text)
  File "C:\Users\LENOVO\Desktop\Academy\env\lib\site-packages\docx\oxml\text\run.py", line 252, in add_text
    for char in text:
TypeError: 'NoneType' object is not iterable
2025-03-17 15:19:59,973 - ERROR - Une erreur est survenue
Traceback (most recent call last):
  File "c:\Users\LENOVO\Desktop\Academy\main.py", line 444, in generer_word
    row_cells[j].text = text
  File "C:\Users\LENOVO\Desktop\Academy\env\lib\site-packages\docx\table.py", line 284, in text
    r.text = text
  File "C:\Users\LENOVO\Desktop\Academy\env\lib\site-packages\docx\oxml\text\run.py", line 129, in text
    _RunContentAppender.append_to_run_from_text(self, text)
  File "C:\Users\LENOVO\Desktop\Academy\env\lib\site-packages\docx\oxml\text\run.py", line 248, in append_to_run_from_text
    appender.add_text(text)
  File "C:\Users\LENOVO\Desktop\Academy\env\lib\site-packages\docx\oxml\text\run.py", line 252, in add_text
    for char in text:
TypeError: 'NoneType' object is not iterable
2025-03-17 15:20:00,005 - ERROR - Une erreur est survenue
Traceback (most recent call last):
  File "c:\Users\LENOVO\Desktop\Academy\main.py", line 444, in generer_word
    row_cells[j].text = text
  File "C:\Users\LENOVO\Desktop\Academy\env\lib\site-packages\docx\table.py", line 284, in text
    r.text = text
  File "C:\Users\LENOVO\Desktop\Academy\env\lib\site-packages\docx\oxml\text\run.py", line 129, in text
    _RunContentAppender.append_to_run_from_text(self, text)
  File "C:\Users\LENOVO\Desktop\Academy\env\lib\site-packages\docx\oxml\text\run.py", line 248, in append_to_run_from_text
    appender.add_text(text)
  File "C:\Users\LENOVO\Desktop\Academy\env\lib\site-packages\docx\oxml\text\run.py", line 252, in add_text
    for char in text:
TypeError: 'NoneType' object is not iterable
2025-03-17 15:20:00,036 - ERROR - Une erreur est survenue
Traceback (most recent call last):
  File "c:\Users\LENOVO\Desktop\Academy\main.py", line 444, in generer_word
    row_cells[j].text = text
  File "C:\Users\LENOVO\Desktop\Academy\env\lib\site-packages\docx\table.py", line 284, in text
    r.text = text
  File "C:\Users\LENOVO\Desktop\Academy\env\lib\site-packages\docx\oxml\text\run.py", line 129, in text
    _RunContentAppender.append_to_run_from_text(self, text)
  File "C:\Users\LENOVO\Desktop\Academy\env\lib\site-packages\docx\oxml\text\run.py", line 248, in append_to_run_from_text
    appender.add_text(text)
  File "C:\Users\LENOVO\Desktop\Academy\env\lib\site-packages\docx\oxml\text\run.py", line 252, in add_text
    for char in text:
TypeError: 'NoneType' object is not iterable
2025-03-17 15:20:00,068 - ERROR - Une erreur est survenue
Traceback (most recent call last):
  File "c:\Users\LENOVO\Desktop\Academy\main.py", line 444, in generer_word
    row_cells[j].text = text
  File "C:\Users\LENOVO\Desktop\Academy\env\lib\site-packages\docx\table.py", line 284, in text
    r.text = text
  File "C:\Users\LENOVO\Desktop\Academy\env\lib\site-packages\docx\oxml\text\run.py", line 129, in text
    _RunContentAppender.append_to_run_from_text(self, text)
  File "C:\Users\LENOVO\Desktop\Academy\env\lib\site-packages\docx\oxml\text\run.py", line 248, in append_to_run_from_text
    appender.add_text(text)
  File "C:\Users\LENOVO\Desktop\Academy\env\lib\site-packages\docx\oxml\text\run.py", line 252, in add_text
    for char in text:
TypeError: 'NoneType' object is not iterable
2025-03-17 15:20:00,099 - ERROR - Une erreur est survenue
Traceback (most recent call last):
  File "c:\Users\LENOVO\Desktop\Academy\main.py", line 444, in generer_word
    row_cells[j].text = text
  File "C:\Users\LENOVO\Desktop\Academy\env\lib\site-packages\docx\table.py", line 284, in text
    r.text = text
  File "C:\Users\LENOVO\Desktop\Academy\env\lib\site-packages\docx\oxml\text\run.py", line 129, in text
    _RunContentAppender.append_to_run_from_text(self, text)
  File "C:\Users\LENOVO\Desktop\Academy\env\lib\site-packages\docx\oxml\text\run.py", line 248, in append_to_run_from_text
    appender.add_text(text)
  File "C:\Users\LENOVO\Desktop\Academy\env\lib\site-packages\docx\oxml\text\run.py", line 252, in add_text
    for char in text:
TypeError: 'NoneType' object is not iterable
2025-03-17 15:20:00,130 - ERROR - Une erreur est survenue
Traceback (most recent call last):
  File "c:\Users\LENOVO\Desktop\Academy\main.py", line 444, in generer_word
    row_cells[j].text = text
  File "C:\Users\LENOVO\Desktop\Academy\env\lib\site-packages\docx\table.py", line 284, in text
    r.text = text
  File "C:\Users\LENOVO\Desktop\Academy\env\lib\site-packages\docx\oxml\text\run.py", line 129, in text
    _RunContentAppender.append_to_run_from_text(self, text)
  File "C:\Users\LENOVO\Desktop\Academy\env\lib\site-packages\docx\oxml\text\run.py", line 248, in append_to_run_from_text
    appender.add_text(text)
  File "C:\Users\LENOVO\Desktop\Academy\env\lib\site-packages\docx\oxml\text\run.py", line 252, in add_text
    for char in text:
TypeError: 'NoneType' object is not iterable
2025-03-17 15:20:00,168 - ERROR - Une erreur est survenue
Traceback (most recent call last):
  File "c:\Users\LENOVO\Desktop\Academy\main.py", line 444, in generer_word
    row_cells[j].text = text
  File "C:\Users\LENOVO\Desktop\Academy\env\lib\site-packages\docx\table.py", line 284, in text
    r.text = text
  File "C:\Users\LENOVO\Desktop\Academy\env\lib\site-packages\docx\oxml\text\run.py", line 129, in text
    _RunContentAppender.append_to_run_from_text(self, text)
  File "C:\Users\LENOVO\Desktop\Academy\env\lib\site-packages\docx\oxml\text\run.py", line 248, in append_to_run_from_text
    appender.add_text(text)
  File "C:\Users\LENOVO\Desktop\Academy\env\lib\site-packages\docx\oxml\text\run.py", line 252, in add_text
    for char in text:
TypeError: 'NoneType' object is not iterable
2025-03-17 15:20:00,194 - ERROR - Une erreur est survenue
Traceback (most recent call last):
  File "c:\Users\LENOVO\Desktop\Academy\main.py", line 444, in generer_word
    row_cells[j].text = text
  File "C:\Users\LENOVO\Desktop\Academy\env\lib\site-packages\docx\table.py", line 284, in text
    r.text = text
  File "C:\Users\LENOVO\Desktop\Academy\env\lib\site-packages\docx\oxml\text\run.py", line 129, in text
    _RunContentAppender.append_to_run_from_text(self, text)
  File "C:\Users\LENOVO\Desktop\Academy\env\lib\site-packages\docx\oxml\text\run.py", line 248, in append_to_run_from_text
    appender.add_text(text)
  File "C:\Users\LENOVO\Desktop\Academy\env\lib\site-packages\docx\oxml\text\run.py", line 252, in add_text
    for char in text:
TypeError: 'NoneType' object is not iterable
2025-03-17 15:20:00,225 - ERROR - Une erreur est survenue
Traceback (most recent call last):
  File "c:\Users\LENOVO\Desktop\Academy\main.py", line 444, in generer_word
    row_cells[j].text = text
  File "C:\Users\LENOVO\Desktop\Academy\env\lib\site-packages\docx\table.py", line 284, in text
    r.text = text
  File "C:\Users\LENOVO\Desktop\Academy\env\lib\site-packages\docx\oxml\text\run.py", line 129, in text
    _RunContentAppender.append_to_run_from_text(self, text)
  File "C:\Users\LENOVO\Desktop\Academy\env\lib\site-packages\docx\oxml\text\run.py", line 248, in append_to_run_from_text
    appender.add_text(text)
  File "C:\Users\LENOVO\Desktop\Academy\env\lib\site-packages\docx\oxml\text\run.py", line 252, in add_text
    for char in text:
TypeError: 'NoneType' object is not iterable
2025-03-17 15:20:00,335 - ERROR - Une erreur est survenue
Traceback (most recent call last):
  File "c:\Users\LENOVO\Desktop\Academy\main.py", line 444, in generer_word
    row_cells[j].text = text
  File "C:\Users\LENOVO\Desktop\Academy\env\lib\site-packages\docx\table.py", line 284, in text
    r.text = text
  File "C:\Users\LENOVO\Desktop\Academy\env\lib\site-packages\docx\oxml\text\run.py", line 129, in text
    _RunContentAppender.append_to_run_from_text(self, text)
  File "C:\Users\LENOVO\Desktop\Academy\env\lib\site-packages\docx\oxml\text\run.py", line 248, in append_to_run_from_text
    appender.add_text(text)
  File "C:\Users\LENOVO\Desktop\Academy\env\lib\site-packages\docx\oxml\text\run.py", line 252, in add_text
    for char in text:
TypeError: 'NoneType' object is not iterable
2025-03-17 15:20:00,368 - ERROR - Une erreur est survenue
Traceback (most recent call last):
  File "c:\Users\LENOVO\Desktop\Academy\main.py", line 444, in generer_word
    row_cells[j].text = text
  File "C:\Users\LENOVO\Desktop\Academy\env\lib\site-packages\docx\table.py", line 284, in text
    r.text = text
  File "C:\Users\LENOVO\Desktop\Academy\env\lib\site-packages\docx\oxml\text\run.py", line 129, in text
    _RunContentAppender.append_to_run_from_text(self, text)
  File "C:\Users\LENOVO\Desktop\Academy\env\lib\site-packages\docx\oxml\text\run.py", line 248, in append_to_run_from_text
    appender.add_text(text)
  File "C:\Users\LENOVO\Desktop\Academy\env\lib\site-packages\docx\oxml\text\run.py", line 252, in add_text
    for char in text:
TypeError: 'NoneType' object is not iterable
2025-03-17 15:20:00,382 - ERROR - Une erreur est survenue
Traceback (most recent call last):
  File "c:\Users\LENOVO\Desktop\Academy\main.py", line 444, in generer_word
    row_cells[j].text = text
  File "C:\Users\LENOVO\Desktop\Academy\env\lib\site-packages\docx\table.py", line 284, in text
    r.text = text
  File "C:\Users\LENOVO\Desktop\Academy\env\lib\site-packages\docx\oxml\text\run.py", line 129, in text
    _RunContentAppender.append_to_run_from_text(self, text)
  File "C:\Users\LENOVO\Desktop\Academy\env\lib\site-packages\docx\oxml\text\run.py", line 248, in append_to_run_from_text
    appender.add_text(text)
  File "C:\Users\LENOVO\Desktop\Academy\env\lib\site-packages\docx\oxml\text\run.py", line 252, in add_text
    for char in text:
TypeError: 'NoneType' object is not iterable
2025-03-17 15:20:00,413 - ERROR - Une erreur est survenue
Traceback (most recent call last):
  File "c:\Users\LENOVO\Desktop\Academy\main.py", line 444, in generer_word
    row_cells[j].text = text
  File "C:\Users\LENOVO\Desktop\Academy\env\lib\site-packages\docx\table.py", line 284, in text
    r.text = text
  File "C:\Users\LENOVO\Desktop\Academy\env\lib\site-packages\docx\oxml\text\run.py", line 129, in text
    _RunContentAppender.append_to_run_from_text(self, text)
  File "C:\Users\LENOVO\Desktop\Academy\env\lib\site-packages\docx\oxml\text\run.py", line 248, in append_to_run_from_text
    appender.add_text(text)
  File "C:\Users\LENOVO\Desktop\Academy\env\lib\site-packages\docx\oxml\text\run.py", line 252, in add_text
    for char in text:
TypeError: 'NoneType' object is not iterable
2025-03-17 15:20:00,476 - ERROR - Une erreur est survenue
Traceback (most recent call last):
  File "c:\Users\LENOVO\Desktop\Academy\main.py", line 444, in generer_word
    row_cells[j].text = text
  File "C:\Users\LENOVO\Desktop\Academy\env\lib\site-packages\docx\table.py", line 284, in text
    r.text = text
  File "C:\Users\LENOVO\Desktop\Academy\env\lib\site-packages\docx\oxml\text\run.py", line 129, in text
    _RunContentAppender.append_to_run_from_text(self, text)
  File "C:\Users\LENOVO\Desktop\Academy\env\lib\site-packages\docx\oxml\text\run.py", line 248, in append_to_run_from_text
    appender.add_text(text)
  File "C:\Users\LENOVO\Desktop\Academy\env\lib\site-packages\docx\oxml\text\run.py", line 252, in add_text
    for char in text:
TypeError: 'NoneType' object is not iterable
2025-03-17 15:20:00,507 - ERROR - Une erreur est survenue
Traceback (most recent call last):
  File "c:\Users\LENOVO\Desktop\Academy\main.py", line 444, in generer_word
    row_cells[j].text = text
  File "C:\Users\LENOVO\Desktop\Academy\env\lib\site-packages\docx\table.py", line 284, in text
    r.text = text
  File "C:\Users\LENOVO\Desktop\Academy\env\lib\site-packages\docx\oxml\text\run.py", line 129, in text
    _RunContentAppender.append_to_run_from_text(self, text)
  File "C:\Users\LENOVO\Desktop\Academy\env\lib\site-packages\docx\oxml\text\run.py", line 248, in append_to_run_from_text
    appender.add_text(text)
  File "C:\Users\LENOVO\Desktop\Academy\env\lib\site-packages\docx\oxml\text\run.py", line 252, in add_text
    for char in text:
TypeError: 'NoneType' object is not iterable
2025-03-17 15:20:01,497 - ERROR - Une erreur est survenue
Traceback (most recent call last):
  File "c:\Users\LENOVO\Desktop\Academy\main.py", line 444, in generer_word
    row_cells[j].text = text
  File "C:\Users\LENOVO\Desktop\Academy\env\lib\site-packages\docx\table.py", line 284, in text
    r.text = text
  File "C:\Users\LENOVO\Desktop\Academy\env\lib\site-packages\docx\oxml\text\run.py", line 129, in text
    _RunContentAppender.append_to_run_from_text(self, text)
  File "C:\Users\LENOVO\Desktop\Academy\env\lib\site-packages\docx\oxml\text\run.py", line 248, in append_to_run_from_text
    appender.add_text(text)
  File "C:\Users\LENOVO\Desktop\Academy\env\lib\site-packages\docx\oxml\text\run.py", line 252, in add_text
    for char in text:
TypeError: 'NoneType' object is not iterable
2025-03-17 15:20:01,622 - ERROR - Une erreur est survenue
Traceback (most recent call last):
  File "c:\Users\LENOVO\Desktop\Academy\main.py", line 444, in generer_word
    row_cells[j].text = text
  File "C:\Users\LENOVO\Desktop\Academy\env\lib\site-packages\docx\table.py", line 284, in text
    r.text = text
  File "C:\Users\LENOVO\Desktop\Academy\env\lib\site-packages\docx\oxml\text\run.py", line 129, in text
    _RunContentAppender.append_to_run_from_text(self, text)
  File "C:\Users\LENOVO\Desktop\Academy\env\lib\site-packages\docx\oxml\text\run.py", line 248, in append_to_run_from_text
    appender.add_text(text)
  File "C:\Users\LENOVO\Desktop\Academy\env\lib\site-packages\docx\oxml\text\run.py", line 252, in add_text
    for char in text:
TypeError: 'NoneType' object is not iterable
2025-03-17 15:20:02,187 - ERROR - Une erreur est survenue
Traceback (most recent call last):
  File "c:\Users\LENOVO\Desktop\Academy\main.py", line 444, in generer_word
    row_cells[j].text = text
  File "C:\Users\LENOVO\Desktop\Academy\env\lib\site-packages\docx\table.py", line 284, in text
    r.text = text
  File "C:\Users\LENOVO\Desktop\Academy\env\lib\site-packages\docx\oxml\text\run.py", line 129, in text
    _RunContentAppender.append_to_run_from_text(self, text)
  File "C:\Users\LENOVO\Desktop\Academy\env\lib\site-packages\docx\oxml\text\run.py", line 248, in append_to_run_from_text
    appender.add_text(text)
  File "C:\Users\LENOVO\Desktop\Academy\env\lib\site-packages\docx\oxml\text\run.py", line 252, in add_text
    for char in text:
TypeError: 'NoneType' object is not iterable
2025-03-17 15:20:02,219 - ERROR - Une erreur est survenue
Traceback (most recent call last):
  File "c:\Users\LENOVO\Desktop\Academy\main.py", line 444, in generer_word
    row_cells[j].text = text
  File "C:\Users\LENOVO\Desktop\Academy\env\lib\site-packages\docx\table.py", line 284, in text
    r.text = text
  File "C:\Users\LENOVO\Desktop\Academy\env\lib\site-packages\docx\oxml\text\run.py", line 129, in text
    _RunContentAppender.append_to_run_from_text(self, text)
  File "C:\Users\LENOVO\Desktop\Academy\env\lib\site-packages\docx\oxml\text\run.py", line 248, in append_to_run_from_text
    appender.add_text(text)
  File "C:\Users\LENOVO\Desktop\Academy\env\lib\site-packages\docx\oxml\text\run.py", line 252, in add_text
    for char in text:
TypeError: 'NoneType' object is not iterable
2025-03-17 15:20:03,757 - ERROR - Une erreur est survenue
Traceback (most recent call last):
  File "c:\Users\LENOVO\Desktop\Academy\main.py", line 444, in generer_word
    row_cells[j].text = text
  File "C:\Users\LENOVO\Desktop\Academy\env\lib\site-packages\docx\table.py", line 284, in text
    r.text = text
  File "C:\Users\LENOVO\Desktop\Academy\env\lib\site-packages\docx\oxml\text\run.py", line 129, in text
    _RunContentAppender.append_to_run_from_text(self, text)
  File "C:\Users\LENOVO\Desktop\Academy\env\lib\site-packages\docx\oxml\text\run.py", line 248, in append_to_run_from_text
    appender.add_text(text)
  File "C:\Users\LENOVO\Desktop\Academy\env\lib\site-packages\docx\oxml\text\run.py", line 252, in add_text
    for char in text:
TypeError: 'NoneType' object is not iterable
2025-03-17 15:22:22,036 - ERROR - Une erreur est survenue
Traceback (most recent call last):
  File "c:\Users\LENOVO\Desktop\Academy\main.py", line 444, in generer_word
    row_cells[j].text = text
  File "C:\Users\LENOVO\Desktop\Academy\env\lib\site-packages\docx\table.py", line 284, in text
    r.text = text
  File "C:\Users\LENOVO\Desktop\Academy\env\lib\site-packages\docx\oxml\text\run.py", line 129, in text
    _RunContentAppender.append_to_run_from_text(self, text)
  File "C:\Users\LENOVO\Desktop\Academy\env\lib\site-packages\docx\oxml\text\run.py", line 248, in append_to_run_from_text
    appender.add_text(text)
  File "C:\Users\LENOVO\Desktop\Academy\env\lib\site-packages\docx\oxml\text\run.py", line 252, in add_text
    for char in text:
TypeError: 'NoneType' object is not iterable
2025-03-17 15:22:22,099 - ERROR - Une erreur est survenue
Traceback (most recent call last):
  File "c:\Users\LENOVO\Desktop\Academy\main.py", line 444, in generer_word
    row_cells[j].text = text
  File "C:\Users\LENOVO\Desktop\Academy\env\lib\site-packages\docx\table.py", line 284, in text
    r.text = text
  File "C:\Users\LENOVO\Desktop\Academy\env\lib\site-packages\docx\oxml\text\run.py", line 129, in text
    _RunContentAppender.append_to_run_from_text(self, text)
  File "C:\Users\LENOVO\Desktop\Academy\env\lib\site-packages\docx\oxml\text\run.py", line 248, in append_to_run_from_text
    appender.add_text(text)
  File "C:\Users\LENOVO\Desktop\Academy\env\lib\site-packages\docx\oxml\text\run.py", line 252, in add_text
    for char in text:
TypeError: 'NoneType' object is not iterable
2025-03-17 15:22:22,115 - ERROR - Une erreur est survenue
Traceback (most recent call last):
  File "c:\Users\LENOVO\Desktop\Academy\main.py", line 444, in generer_word
    row_cells[j].text = text
  File "C:\Users\LENOVO\Desktop\Academy\env\lib\site-packages\docx\table.py", line 284, in text
    r.text = text
  File "C:\Users\LENOVO\Desktop\Academy\env\lib\site-packages\docx\oxml\text\run.py", line 129, in text
    _RunContentAppender.append_to_run_from_text(self, text)
  File "C:\Users\LENOVO\Desktop\Academy\env\lib\site-packages\docx\oxml\text\run.py", line 248, in append_to_run_from_text
    appender.add_text(text)
  File "C:\Users\LENOVO\Desktop\Academy\env\lib\site-packages\docx\oxml\text\run.py", line 252, in add_text
    for char in text:
TypeError: 'NoneType' object is not iterable
2025-03-17 15:22:22,178 - ERROR - Une erreur est survenue
Traceback (most recent call last):
  File "c:\Users\LENOVO\Desktop\Academy\main.py", line 444, in generer_word
    row_cells[j].text = text
  File "C:\Users\LENOVO\Desktop\Academy\env\lib\site-packages\docx\table.py", line 284, in text
    r.text = text
  File "C:\Users\LENOVO\Desktop\Academy\env\lib\site-packages\docx\oxml\text\run.py", line 129, in text
    _RunContentAppender.append_to_run_from_text(self, text)
  File "C:\Users\LENOVO\Desktop\Academy\env\lib\site-packages\docx\oxml\text\run.py", line 248, in append_to_run_from_text
    appender.add_text(text)
  File "C:\Users\LENOVO\Desktop\Academy\env\lib\site-packages\docx\oxml\text\run.py", line 252, in add_text
    for char in text:
TypeError: 'NoneType' object is not iterable
2025-03-17 15:22:23,402 - ERROR - Une erreur est survenue
Traceback (most recent call last):
  File "c:\Users\LENOVO\Desktop\Academy\main.py", line 444, in generer_word
    row_cells[j].text = text
  File "C:\Users\LENOVO\Desktop\Academy\env\lib\site-packages\docx\table.py", line 284, in text
    r.text = text
  File "C:\Users\LENOVO\Desktop\Academy\env\lib\site-packages\docx\oxml\text\run.py", line 129, in text
    _RunContentAppender.append_to_run_from_text(self, text)
  File "C:\Users\LENOVO\Desktop\Academy\env\lib\site-packages\docx\oxml\text\run.py", line 248, in append_to_run_from_text
    appender.add_text(text)
  File "C:\Users\LENOVO\Desktop\Academy\env\lib\site-packages\docx\oxml\text\run.py", line 252, in add_text
    for char in text:
TypeError: 'NoneType' object is not iterable
2025-03-17 15:22:23,433 - ERROR - Une erreur est survenue
Traceback (most recent call last):
  File "c:\Users\LENOVO\Desktop\Academy\main.py", line 444, in generer_word
    row_cells[j].text = text
  File "C:\Users\LENOVO\Desktop\Academy\env\lib\site-packages\docx\table.py", line 284, in text
    r.text = text
  File "C:\Users\LENOVO\Desktop\Academy\env\lib\site-packages\docx\oxml\text\run.py", line 129, in text
    _RunContentAppender.append_to_run_from_text(self, text)
  File "C:\Users\LENOVO\Desktop\Academy\env\lib\site-packages\docx\oxml\text\run.py", line 248, in append_to_run_from_text
    appender.add_text(text)
  File "C:\Users\LENOVO\Desktop\Academy\env\lib\site-packages\docx\oxml\text\run.py", line 252, in add_text
    for char in text:
TypeError: 'NoneType' object is not iterable
2025-03-17 15:22:23,454 - ERROR - Une erreur est survenue
Traceback (most recent call last):
  File "c:\Users\LENOVO\Desktop\Academy\main.py", line 444, in generer_word
    row_cells[j].text = text
  File "C:\Users\LENOVO\Desktop\Academy\env\lib\site-packages\docx\table.py", line 284, in text
    r.text = text
  File "C:\Users\LENOVO\Desktop\Academy\env\lib\site-packages\docx\oxml\text\run.py", line 129, in text
    _RunContentAppender.append_to_run_from_text(self, text)
  File "C:\Users\LENOVO\Desktop\Academy\env\lib\site-packages\docx\oxml\text\run.py", line 248, in append_to_run_from_text
    appender.add_text(text)
  File "C:\Users\LENOVO\Desktop\Academy\env\lib\site-packages\docx\oxml\text\run.py", line 252, in add_text
    for char in text:
TypeError: 'NoneType' object is not iterable
2025-03-17 15:22:23,481 - ERROR - Une erreur est survenue
Traceback (most recent call last):
  File "c:\Users\LENOVO\Desktop\Academy\main.py", line 444, in generer_word
    row_cells[j].text = text
  File "C:\Users\LENOVO\Desktop\Academy\env\lib\site-packages\docx\table.py", line 284, in text
    r.text = text
  File "C:\Users\LENOVO\Desktop\Academy\env\lib\site-packages\docx\oxml\text\run.py", line 129, in text
    _RunContentAppender.append_to_run_from_text(self, text)
  File "C:\Users\LENOVO\Desktop\Academy\env\lib\site-packages\docx\oxml\text\run.py", line 248, in append_to_run_from_text
    appender.add_text(text)
  File "C:\Users\LENOVO\Desktop\Academy\env\lib\site-packages\docx\oxml\text\run.py", line 252, in add_text
    for char in text:
TypeError: 'NoneType' object is not iterable
2025-03-17 15:22:23,512 - ERROR - Une erreur est survenue
Traceback (most recent call last):
  File "c:\Users\LENOVO\Desktop\Academy\main.py", line 444, in generer_word
    row_cells[j].text = text
  File "C:\Users\LENOVO\Desktop\Academy\env\lib\site-packages\docx\table.py", line 284, in text
    r.text = text
  File "C:\Users\LENOVO\Desktop\Academy\env\lib\site-packages\docx\oxml\text\run.py", line 129, in text
    _RunContentAppender.append_to_run_from_text(self, text)
  File "C:\Users\LENOVO\Desktop\Academy\env\lib\site-packages\docx\oxml\text\run.py", line 248, in append_to_run_from_text
    appender.add_text(text)
  File "C:\Users\LENOVO\Desktop\Academy\env\lib\site-packages\docx\oxml\text\run.py", line 252, in add_text
    for char in text:
TypeError: 'NoneType' object is not iterable
2025-03-17 15:22:23,543 - ERROR - Une erreur est survenue
Traceback (most recent call last):
  File "c:\Users\LENOVO\Desktop\Academy\main.py", line 444, in generer_word
    row_cells[j].text = text
  File "C:\Users\LENOVO\Desktop\Academy\env\lib\site-packages\docx\table.py", line 284, in text
    r.text = text
  File "C:\Users\LENOVO\Desktop\Academy\env\lib\site-packages\docx\oxml\text\run.py", line 129, in text
    _RunContentAppender.append_to_run_from_text(self, text)
  File "C:\Users\LENOVO\Desktop\Academy\env\lib\site-packages\docx\oxml\text\run.py", line 248, in append_to_run_from_text
    appender.add_text(text)
  File "C:\Users\LENOVO\Desktop\Academy\env\lib\site-packages\docx\oxml\text\run.py", line 252, in add_text
    for char in text:
TypeError: 'NoneType' object is not iterable
2025-03-17 15:22:23,559 - ERROR - Une erreur est survenue
Traceback (most recent call last):
  File "c:\Users\LENOVO\Desktop\Academy\main.py", line 444, in generer_word
    row_cells[j].text = text
  File "C:\Users\LENOVO\Desktop\Academy\env\lib\site-packages\docx\table.py", line 284, in text
    r.text = text
  File "C:\Users\LENOVO\Desktop\Academy\env\lib\site-packages\docx\oxml\text\run.py", line 129, in text
    _RunContentAppender.append_to_run_from_text(self, text)
  File "C:\Users\LENOVO\Desktop\Academy\env\lib\site-packages\docx\oxml\text\run.py", line 248, in append_to_run_from_text
    appender.add_text(text)
  File "C:\Users\LENOVO\Desktop\Academy\env\lib\site-packages\docx\oxml\text\run.py", line 252, in add_text
    for char in text:
TypeError: 'NoneType' object is not iterable
2025-03-17 15:22:23,591 - ERROR - Une erreur est survenue
Traceback (most recent call last):
  File "c:\Users\LENOVO\Desktop\Academy\main.py", line 444, in generer_word
    row_cells[j].text = text
  File "C:\Users\LENOVO\Desktop\Academy\env\lib\site-packages\docx\table.py", line 284, in text
    r.text = text
  File "C:\Users\LENOVO\Desktop\Academy\env\lib\site-packages\docx\oxml\text\run.py", line 129, in text
    _RunContentAppender.append_to_run_from_text(self, text)
  File "C:\Users\LENOVO\Desktop\Academy\env\lib\site-packages\docx\oxml\text\run.py", line 248, in append_to_run_from_text
    appender.add_text(text)
  File "C:\Users\LENOVO\Desktop\Academy\env\lib\site-packages\docx\oxml\text\run.py", line 252, in add_text
    for char in text:
TypeError: 'NoneType' object is not iterable
2025-03-17 15:22:23,622 - ERROR - Une erreur est survenue
Traceback (most recent call last):
  File "c:\Users\LENOVO\Desktop\Academy\main.py", line 444, in generer_word
    row_cells[j].text = text
  File "C:\Users\LENOVO\Desktop\Academy\env\lib\site-packages\docx\table.py", line 284, in text
    r.text = text
  File "C:\Users\LENOVO\Desktop\Academy\env\lib\site-packages\docx\oxml\text\run.py", line 129, in text
    _RunContentAppender.append_to_run_from_text(self, text)
  File "C:\Users\LENOVO\Desktop\Academy\env\lib\site-packages\docx\oxml\text\run.py", line 248, in append_to_run_from_text
    appender.add_text(text)
  File "C:\Users\LENOVO\Desktop\Academy\env\lib\site-packages\docx\oxml\text\run.py", line 252, in add_text
    for char in text:
TypeError: 'NoneType' object is not iterable
2025-03-17 15:22:23,637 - ERROR - Une erreur est survenue
Traceback (most recent call last):
  File "c:\Users\LENOVO\Desktop\Academy\main.py", line 444, in generer_word
    row_cells[j].text = text
  File "C:\Users\LENOVO\Desktop\Academy\env\lib\site-packages\docx\table.py", line 284, in text
    r.text = text
  File "C:\Users\LENOVO\Desktop\Academy\env\lib\site-packages\docx\oxml\text\run.py", line 129, in text
    _RunContentAppender.append_to_run_from_text(self, text)
  File "C:\Users\LENOVO\Desktop\Academy\env\lib\site-packages\docx\oxml\text\run.py", line 248, in append_to_run_from_text
    appender.add_text(text)
  File "C:\Users\LENOVO\Desktop\Academy\env\lib\site-packages\docx\oxml\text\run.py", line 252, in add_text
    for char in text:
TypeError: 'NoneType' object is not iterable
2025-03-17 15:22:23,669 - ERROR - Une erreur est survenue
Traceback (most recent call last):
  File "c:\Users\LENOVO\Desktop\Academy\main.py", line 444, in generer_word
    row_cells[j].text = text
  File "C:\Users\LENOVO\Desktop\Academy\env\lib\site-packages\docx\table.py", line 284, in text
    r.text = text
  File "C:\Users\LENOVO\Desktop\Academy\env\lib\site-packages\docx\oxml\text\run.py", line 129, in text
    _RunContentAppender.append_to_run_from_text(self, text)
  File "C:\Users\LENOVO\Desktop\Academy\env\lib\site-packages\docx\oxml\text\run.py", line 248, in append_to_run_from_text
    appender.add_text(text)
  File "C:\Users\LENOVO\Desktop\Academy\env\lib\site-packages\docx\oxml\text\run.py", line 252, in add_text
    for char in text:
TypeError: 'NoneType' object is not iterable
2025-03-17 15:22:23,701 - ERROR - Une erreur est survenue
Traceback (most recent call last):
  File "c:\Users\LENOVO\Desktop\Academy\main.py", line 444, in generer_word
    row_cells[j].text = text
  File "C:\Users\LENOVO\Desktop\Academy\env\lib\site-packages\docx\table.py", line 284, in text
    r.text = text
  File "C:\Users\LENOVO\Desktop\Academy\env\lib\site-packages\docx\oxml\text\run.py", line 129, in text
    _RunContentAppender.append_to_run_from_text(self, text)
  File "C:\Users\LENOVO\Desktop\Academy\env\lib\site-packages\docx\oxml\text\run.py", line 248, in append_to_run_from_text
    appender.add_text(text)
  File "C:\Users\LENOVO\Desktop\Academy\env\lib\site-packages\docx\oxml\text\run.py", line 252, in add_text
    for char in text:
TypeError: 'NoneType' object is not iterable
2025-03-17 15:22:23,701 - ERROR - Une erreur est survenue
Traceback (most recent call last):
  File "c:\Users\LENOVO\Desktop\Academy\main.py", line 444, in generer_word
    row_cells[j].text = text
  File "C:\Users\LENOVO\Desktop\Academy\env\lib\site-packages\docx\table.py", line 284, in text
    r.text = text
  File "C:\Users\LENOVO\Desktop\Academy\env\lib\site-packages\docx\oxml\text\run.py", line 129, in text
    _RunContentAppender.append_to_run_from_text(self, text)
  File "C:\Users\LENOVO\Desktop\Academy\env\lib\site-packages\docx\oxml\text\run.py", line 248, in append_to_run_from_text
    appender.add_text(text)
  File "C:\Users\LENOVO\Desktop\Academy\env\lib\site-packages\docx\oxml\text\run.py", line 252, in add_text
    for char in text:
TypeError: 'NoneType' object is not iterable
2025-03-17 15:22:23,732 - ERROR - Une erreur est survenue
Traceback (most recent call last):
  File "c:\Users\LENOVO\Desktop\Academy\main.py", line 444, in generer_word
    row_cells[j].text = text
  File "C:\Users\LENOVO\Desktop\Academy\env\lib\site-packages\docx\table.py", line 284, in text
    r.text = text
  File "C:\Users\LENOVO\Desktop\Academy\env\lib\site-packages\docx\oxml\text\run.py", line 129, in text
    _RunContentAppender.append_to_run_from_text(self, text)
  File "C:\Users\LENOVO\Desktop\Academy\env\lib\site-packages\docx\oxml\text\run.py", line 248, in append_to_run_from_text
    appender.add_text(text)
  File "C:\Users\LENOVO\Desktop\Academy\env\lib\site-packages\docx\oxml\text\run.py", line 252, in add_text
    for char in text:
TypeError: 'NoneType' object is not iterable
2025-03-17 15:22:23,779 - ERROR - Une erreur est survenue
Traceback (most recent call last):
  File "c:\Users\LENOVO\Desktop\Academy\main.py", line 444, in generer_word
    row_cells[j].text = text
  File "C:\Users\LENOVO\Desktop\Academy\env\lib\site-packages\docx\table.py", line 284, in text
    r.text = text
  File "C:\Users\LENOVO\Desktop\Academy\env\lib\site-packages\docx\oxml\text\run.py", line 129, in text
    _RunContentAppender.append_to_run_from_text(self, text)
  File "C:\Users\LENOVO\Desktop\Academy\env\lib\site-packages\docx\oxml\text\run.py", line 248, in append_to_run_from_text
    appender.add_text(text)
  File "C:\Users\LENOVO\Desktop\Academy\env\lib\site-packages\docx\oxml\text\run.py", line 252, in add_text
    for char in text:
TypeError: 'NoneType' object is not iterable
2025-03-17 15:22:23,810 - ERROR - Une erreur est survenue
Traceback (most recent call last):
  File "c:\Users\LENOVO\Desktop\Academy\main.py", line 444, in generer_word
    row_cells[j].text = text
  File "C:\Users\LENOVO\Desktop\Academy\env\lib\site-packages\docx\table.py", line 284, in text
    r.text = text
  File "C:\Users\LENOVO\Desktop\Academy\env\lib\site-packages\docx\oxml\text\run.py", line 129, in text
    _RunContentAppender.append_to_run_from_text(self, text)
  File "C:\Users\LENOVO\Desktop\Academy\env\lib\site-packages\docx\oxml\text\run.py", line 248, in append_to_run_from_text
    appender.add_text(text)
  File "C:\Users\LENOVO\Desktop\Academy\env\lib\site-packages\docx\oxml\text\run.py", line 252, in add_text
    for char in text:
TypeError: 'NoneType' object is not iterable
2025-03-17 15:22:23,826 - ERROR - Une erreur est survenue
Traceback (most recent call last):
  File "c:\Users\LENOVO\Desktop\Academy\main.py", line 444, in generer_word
    row_cells[j].text = text
  File "C:\Users\LENOVO\Desktop\Academy\env\lib\site-packages\docx\table.py", line 284, in text
    r.text = text
  File "C:\Users\LENOVO\Desktop\Academy\env\lib\site-packages\docx\oxml\text\run.py", line 129, in text
    _RunContentAppender.append_to_run_from_text(self, text)
  File "C:\Users\LENOVO\Desktop\Academy\env\lib\site-packages\docx\oxml\text\run.py", line 248, in append_to_run_from_text
    appender.add_text(text)
  File "C:\Users\LENOVO\Desktop\Academy\env\lib\site-packages\docx\oxml\text\run.py", line 252, in add_text
    for char in text:
TypeError: 'NoneType' object is not iterable
2025-03-17 15:22:23,858 - ERROR - Une erreur est survenue
Traceback (most recent call last):
  File "c:\Users\LENOVO\Desktop\Academy\main.py", line 444, in generer_word
    row_cells[j].text = text
  File "C:\Users\LENOVO\Desktop\Academy\env\lib\site-packages\docx\table.py", line 284, in text
    r.text = text
  File "C:\Users\LENOVO\Desktop\Academy\env\lib\site-packages\docx\oxml\text\run.py", line 129, in text
    _RunContentAppender.append_to_run_from_text(self, text)
  File "C:\Users\LENOVO\Desktop\Academy\env\lib\site-packages\docx\oxml\text\run.py", line 248, in append_to_run_from_text
    appender.add_text(text)
  File "C:\Users\LENOVO\Desktop\Academy\env\lib\site-packages\docx\oxml\text\run.py", line 252, in add_text
    for char in text:
TypeError: 'NoneType' object is not iterable
2025-03-17 15:22:23,889 - ERROR - Une erreur est survenue
Traceback (most recent call last):
  File "c:\Users\LENOVO\Desktop\Academy\main.py", line 444, in generer_word
    row_cells[j].text = text
  File "C:\Users\LENOVO\Desktop\Academy\env\lib\site-packages\docx\table.py", line 284, in text
    r.text = text
  File "C:\Users\LENOVO\Desktop\Academy\env\lib\site-packages\docx\oxml\text\run.py", line 129, in text
    _RunContentAppender.append_to_run_from_text(self, text)
  File "C:\Users\LENOVO\Desktop\Academy\env\lib\site-packages\docx\oxml\text\run.py", line 248, in append_to_run_from_text
    appender.add_text(text)
  File "C:\Users\LENOVO\Desktop\Academy\env\lib\site-packages\docx\oxml\text\run.py", line 252, in add_text
    for char in text:
TypeError: 'NoneType' object is not iterable
2025-03-17 15:22:23,905 - ERROR - Une erreur est survenue
Traceback (most recent call last):
  File "c:\Users\LENOVO\Desktop\Academy\main.py", line 444, in generer_word
    row_cells[j].text = text
  File "C:\Users\LENOVO\Desktop\Academy\env\lib\site-packages\docx\table.py", line 284, in text
    r.text = text
  File "C:\Users\LENOVO\Desktop\Academy\env\lib\site-packages\docx\oxml\text\run.py", line 129, in text
    _RunContentAppender.append_to_run_from_text(self, text)
  File "C:\Users\LENOVO\Desktop\Academy\env\lib\site-packages\docx\oxml\text\run.py", line 248, in append_to_run_from_text
    appender.add_text(text)
  File "C:\Users\LENOVO\Desktop\Academy\env\lib\site-packages\docx\oxml\text\run.py", line 252, in add_text
    for char in text:
TypeError: 'NoneType' object is not iterable
2025-03-17 15:22:23,968 - ERROR - Une erreur est survenue
Traceback (most recent call last):
  File "c:\Users\LENOVO\Desktop\Academy\main.py", line 444, in generer_word
    row_cells[j].text = text
  File "C:\Users\LENOVO\Desktop\Academy\env\lib\site-packages\docx\table.py", line 284, in text
    r.text = text
  File "C:\Users\LENOVO\Desktop\Academy\env\lib\site-packages\docx\oxml\text\run.py", line 129, in text
    _RunContentAppender.append_to_run_from_text(self, text)
  File "C:\Users\LENOVO\Desktop\Academy\env\lib\site-packages\docx\oxml\text\run.py", line 248, in append_to_run_from_text
    appender.add_text(text)
  File "C:\Users\LENOVO\Desktop\Academy\env\lib\site-packages\docx\oxml\text\run.py", line 252, in add_text
    for char in text:
TypeError: 'NoneType' object is not iterable
2025-03-17 15:22:23,999 - ERROR - Une erreur est survenue
Traceback (most recent call last):
  File "c:\Users\LENOVO\Desktop\Academy\main.py", line 444, in generer_word
    row_cells[j].text = text
  File "C:\Users\LENOVO\Desktop\Academy\env\lib\site-packages\docx\table.py", line 284, in text
    r.text = text
  File "C:\Users\LENOVO\Desktop\Academy\env\lib\site-packages\docx\oxml\text\run.py", line 129, in text
    _RunContentAppender.append_to_run_from_text(self, text)
  File "C:\Users\LENOVO\Desktop\Academy\env\lib\site-packages\docx\oxml\text\run.py", line 248, in append_to_run_from_text
    appender.add_text(text)
  File "C:\Users\LENOVO\Desktop\Academy\env\lib\site-packages\docx\oxml\text\run.py", line 252, in add_text
    for char in text:
TypeError: 'NoneType' object is not iterable
2025-03-17 15:22:24,062 - ERROR - Une erreur est survenue
Traceback (most recent call last):
  File "c:\Users\LENOVO\Desktop\Academy\main.py", line 444, in generer_word
    row_cells[j].text = text
  File "C:\Users\LENOVO\Desktop\Academy\env\lib\site-packages\docx\table.py", line 284, in text
    r.text = text
  File "C:\Users\LENOVO\Desktop\Academy\env\lib\site-packages\docx\oxml\text\run.py", line 129, in text
    _RunContentAppender.append_to_run_from_text(self, text)
  File "C:\Users\LENOVO\Desktop\Academy\env\lib\site-packages\docx\oxml\text\run.py", line 248, in append_to_run_from_text
    appender.add_text(text)
  File "C:\Users\LENOVO\Desktop\Academy\env\lib\site-packages\docx\oxml\text\run.py", line 252, in add_text
    for char in text:
TypeError: 'NoneType' object is not iterable
2025-03-17 15:22:24,093 - ERROR - Une erreur est survenue
Traceback (most recent call last):
  File "c:\Users\LENOVO\Desktop\Academy\main.py", line 444, in generer_word
    row_cells[j].text = text
  File "C:\Users\LENOVO\Desktop\Academy\env\lib\site-packages\docx\table.py", line 284, in text
    r.text = text
  File "C:\Users\LENOVO\Desktop\Academy\env\lib\site-packages\docx\oxml\text\run.py", line 129, in text
    _RunContentAppender.append_to_run_from_text(self, text)
  File "C:\Users\LENOVO\Desktop\Academy\env\lib\site-packages\docx\oxml\text\run.py", line 248, in append_to_run_from_text
    appender.add_text(text)
  File "C:\Users\LENOVO\Desktop\Academy\env\lib\site-packages\docx\oxml\text\run.py", line 252, in add_text
    for char in text:
TypeError: 'NoneType' object is not iterable
2025-03-17 15:22:24,124 - ERROR - Une erreur est survenue
Traceback (most recent call last):
  File "c:\Users\LENOVO\Desktop\Academy\main.py", line 444, in generer_word
    row_cells[j].text = text
  File "C:\Users\LENOVO\Desktop\Academy\env\lib\site-packages\docx\table.py", line 284, in text
    r.text = text
  File "C:\Users\LENOVO\Desktop\Academy\env\lib\site-packages\docx\oxml\text\run.py", line 129, in text
    _RunContentAppender.append_to_run_from_text(self, text)
  File "C:\Users\LENOVO\Desktop\Academy\env\lib\site-packages\docx\oxml\text\run.py", line 248, in append_to_run_from_text
    appender.add_text(text)
  File "C:\Users\LENOVO\Desktop\Academy\env\lib\site-packages\docx\oxml\text\run.py", line 252, in add_text
    for char in text:
TypeError: 'NoneType' object is not iterable
2025-03-17 15:22:24,155 - ERROR - Une erreur est survenue
Traceback (most recent call last):
  File "c:\Users\LENOVO\Desktop\Academy\main.py", line 444, in generer_word
    row_cells[j].text = text
  File "C:\Users\LENOVO\Desktop\Academy\env\lib\site-packages\docx\table.py", line 284, in text
    r.text = text
  File "C:\Users\LENOVO\Desktop\Academy\env\lib\site-packages\docx\oxml\text\run.py", line 129, in text
    _RunContentAppender.append_to_run_from_text(self, text)
  File "C:\Users\LENOVO\Desktop\Academy\env\lib\site-packages\docx\oxml\text\run.py", line 248, in append_to_run_from_text
    appender.add_text(text)
  File "C:\Users\LENOVO\Desktop\Academy\env\lib\site-packages\docx\oxml\text\run.py", line 252, in add_text
    for char in text:
TypeError: 'NoneType' object is not iterable
2025-03-17 15:22:24,172 - ERROR - Une erreur est survenue
Traceback (most recent call last):
  File "c:\Users\LENOVO\Desktop\Academy\main.py", line 444, in generer_word
    row_cells[j].text = text
  File "C:\Users\LENOVO\Desktop\Academy\env\lib\site-packages\docx\table.py", line 284, in text
    r.text = text
  File "C:\Users\LENOVO\Desktop\Academy\env\lib\site-packages\docx\oxml\text\run.py", line 129, in text
    _RunContentAppender.append_to_run_from_text(self, text)
  File "C:\Users\LENOVO\Desktop\Academy\env\lib\site-packages\docx\oxml\text\run.py", line 248, in append_to_run_from_text
    appender.add_text(text)
  File "C:\Users\LENOVO\Desktop\Academy\env\lib\site-packages\docx\oxml\text\run.py", line 252, in add_text
    for char in text:
TypeError: 'NoneType' object is not iterable
2025-03-17 15:22:24,203 - ERROR - Une erreur est survenue
Traceback (most recent call last):
  File "c:\Users\LENOVO\Desktop\Academy\main.py", line 444, in generer_word
    row_cells[j].text = text
  File "C:\Users\LENOVO\Desktop\Academy\env\lib\site-packages\docx\table.py", line 284, in text
    r.text = text
  File "C:\Users\LENOVO\Desktop\Academy\env\lib\site-packages\docx\oxml\text\run.py", line 129, in text
    _RunContentAppender.append_to_run_from_text(self, text)
  File "C:\Users\LENOVO\Desktop\Academy\env\lib\site-packages\docx\oxml\text\run.py", line 248, in append_to_run_from_text
    appender.add_text(text)
  File "C:\Users\LENOVO\Desktop\Academy\env\lib\site-packages\docx\oxml\text\run.py", line 252, in add_text
    for char in text:
TypeError: 'NoneType' object is not iterable
2025-03-17 15:22:24,234 - ERROR - Une erreur est survenue
Traceback (most recent call last):
  File "c:\Users\LENOVO\Desktop\Academy\main.py", line 444, in generer_word
    row_cells[j].text = text
  File "C:\Users\LENOVO\Desktop\Academy\env\lib\site-packages\docx\table.py", line 284, in text
    r.text = text
  File "C:\Users\LENOVO\Desktop\Academy\env\lib\site-packages\docx\oxml\text\run.py", line 129, in text
    _RunContentAppender.append_to_run_from_text(self, text)
  File "C:\Users\LENOVO\Desktop\Academy\env\lib\site-packages\docx\oxml\text\run.py", line 248, in append_to_run_from_text
    appender.add_text(text)
  File "C:\Users\LENOVO\Desktop\Academy\env\lib\site-packages\docx\oxml\text\run.py", line 252, in add_text
    for char in text:
TypeError: 'NoneType' object is not iterable
2025-03-17 15:22:24,266 - ERROR - Une erreur est survenue
Traceback (most recent call last):
  File "c:\Users\LENOVO\Desktop\Academy\main.py", line 444, in generer_word
    row_cells[j].text = text
  File "C:\Users\LENOVO\Desktop\Academy\env\lib\site-packages\docx\table.py", line 284, in text
    r.text = text
  File "C:\Users\LENOVO\Desktop\Academy\env\lib\site-packages\docx\oxml\text\run.py", line 129, in text
    _RunContentAppender.append_to_run_from_text(self, text)
  File "C:\Users\LENOVO\Desktop\Academy\env\lib\site-packages\docx\oxml\text\run.py", line 248, in append_to_run_from_text
    appender.add_text(text)
  File "C:\Users\LENOVO\Desktop\Academy\env\lib\site-packages\docx\oxml\text\run.py", line 252, in add_text
    for char in text:
TypeError: 'NoneType' object is not iterable
2025-03-17 15:22:24,297 - ERROR - Une erreur est survenue
Traceback (most recent call last):
  File "c:\Users\LENOVO\Desktop\Academy\main.py", line 444, in generer_word
    row_cells[j].text = text
  File "C:\Users\LENOVO\Desktop\Academy\env\lib\site-packages\docx\table.py", line 284, in text
    r.text = text
  File "C:\Users\LENOVO\Desktop\Academy\env\lib\site-packages\docx\oxml\text\run.py", line 129, in text
    _RunContentAppender.append_to_run_from_text(self, text)
  File "C:\Users\LENOVO\Desktop\Academy\env\lib\site-packages\docx\oxml\text\run.py", line 248, in append_to_run_from_text
    appender.add_text(text)
  File "C:\Users\LENOVO\Desktop\Academy\env\lib\site-packages\docx\oxml\text\run.py", line 252, in add_text
    for char in text:
TypeError: 'NoneType' object is not iterable
2025-03-17 15:22:24,313 - ERROR - Une erreur est survenue
Traceback (most recent call last):
  File "c:\Users\LENOVO\Desktop\Academy\main.py", line 444, in generer_word
    row_cells[j].text = text
  File "C:\Users\LENOVO\Desktop\Academy\env\lib\site-packages\docx\table.py", line 284, in text
    r.text = text
  File "C:\Users\LENOVO\Desktop\Academy\env\lib\site-packages\docx\oxml\text\run.py", line 129, in text
    _RunContentAppender.append_to_run_from_text(self, text)
  File "C:\Users\LENOVO\Desktop\Academy\env\lib\site-packages\docx\oxml\text\run.py", line 248, in append_to_run_from_text
    appender.add_text(text)
  File "C:\Users\LENOVO\Desktop\Academy\env\lib\site-packages\docx\oxml\text\run.py", line 252, in add_text
    for char in text:
TypeError: 'NoneType' object is not iterable
2025-03-17 15:22:24,344 - ERROR - Une erreur est survenue
Traceback (most recent call last):
  File "c:\Users\LENOVO\Desktop\Academy\main.py", line 444, in generer_word
    row_cells[j].text = text
  File "C:\Users\LENOVO\Desktop\Academy\env\lib\site-packages\docx\table.py", line 284, in text
    r.text = text
  File "C:\Users\LENOVO\Desktop\Academy\env\lib\site-packages\docx\oxml\text\run.py", line 129, in text
    _RunContentAppender.append_to_run_from_text(self, text)
  File "C:\Users\LENOVO\Desktop\Academy\env\lib\site-packages\docx\oxml\text\run.py", line 248, in append_to_run_from_text
    appender.add_text(text)
  File "C:\Users\LENOVO\Desktop\Academy\env\lib\site-packages\docx\oxml\text\run.py", line 252, in add_text
    for char in text:
TypeError: 'NoneType' object is not iterable
2025-03-17 15:22:24,376 - ERROR - Une erreur est survenue
Traceback (most recent call last):
  File "c:\Users\LENOVO\Desktop\Academy\main.py", line 444, in generer_word
    row_cells[j].text = text
  File "C:\Users\LENOVO\Desktop\Academy\env\lib\site-packages\docx\table.py", line 284, in text
    r.text = text
  File "C:\Users\LENOVO\Desktop\Academy\env\lib\site-packages\docx\oxml\text\run.py", line 129, in text
    _RunContentAppender.append_to_run_from_text(self, text)
  File "C:\Users\LENOVO\Desktop\Academy\env\lib\site-packages\docx\oxml\text\run.py", line 248, in append_to_run_from_text
    appender.add_text(text)
  File "C:\Users\LENOVO\Desktop\Academy\env\lib\site-packages\docx\oxml\text\run.py", line 252, in add_text
    for char in text:
TypeError: 'NoneType' object is not iterable
2025-03-17 15:22:24,423 - ERROR - Une erreur est survenue
Traceback (most recent call last):
  File "c:\Users\LENOVO\Desktop\Academy\main.py", line 444, in generer_word
    row_cells[j].text = text
  File "C:\Users\LENOVO\Desktop\Academy\env\lib\site-packages\docx\table.py", line 284, in text
    r.text = text
  File "C:\Users\LENOVO\Desktop\Academy\env\lib\site-packages\docx\oxml\text\run.py", line 129, in text
    _RunContentAppender.append_to_run_from_text(self, text)
  File "C:\Users\LENOVO\Desktop\Academy\env\lib\site-packages\docx\oxml\text\run.py", line 248, in append_to_run_from_text
    appender.add_text(text)
  File "C:\Users\LENOVO\Desktop\Academy\env\lib\site-packages\docx\oxml\text\run.py", line 252, in add_text
    for char in text:
TypeError: 'NoneType' object is not iterable
2025-03-17 15:22:24,456 - ERROR - Une erreur est survenue
Traceback (most recent call last):
  File "c:\Users\LENOVO\Desktop\Academy\main.py", line 444, in generer_word
    row_cells[j].text = text
  File "C:\Users\LENOVO\Desktop\Academy\env\lib\site-packages\docx\table.py", line 284, in text
    r.text = text
  File "C:\Users\LENOVO\Desktop\Academy\env\lib\site-packages\docx\oxml\text\run.py", line 129, in text
    _RunContentAppender.append_to_run_from_text(self, text)
  File "C:\Users\LENOVO\Desktop\Academy\env\lib\site-packages\docx\oxml\text\run.py", line 248, in append_to_run_from_text
    appender.add_text(text)
  File "C:\Users\LENOVO\Desktop\Academy\env\lib\site-packages\docx\oxml\text\run.py", line 252, in add_text
    for char in text:
TypeError: 'NoneType' object is not iterable
2025-03-17 15:22:24,486 - ERROR - Une erreur est survenue
Traceback (most recent call last):
  File "c:\Users\LENOVO\Desktop\Academy\main.py", line 444, in generer_word
    row_cells[j].text = text
  File "C:\Users\LENOVO\Desktop\Academy\env\lib\site-packages\docx\table.py", line 284, in text
    r.text = text
  File "C:\Users\LENOVO\Desktop\Academy\env\lib\site-packages\docx\oxml\text\run.py", line 129, in text
    _RunContentAppender.append_to_run_from_text(self, text)
  File "C:\Users\LENOVO\Desktop\Academy\env\lib\site-packages\docx\oxml\text\run.py", line 248, in append_to_run_from_text
    appender.add_text(text)
  File "C:\Users\LENOVO\Desktop\Academy\env\lib\site-packages\docx\oxml\text\run.py", line 252, in add_text
    for char in text:
TypeError: 'NoneType' object is not iterable
2025-03-17 15:22:24,517 - ERROR - Une erreur est survenue
Traceback (most recent call last):
  File "c:\Users\LENOVO\Desktop\Academy\main.py", line 444, in generer_word
    row_cells[j].text = text
  File "C:\Users\LENOVO\Desktop\Academy\env\lib\site-packages\docx\table.py", line 284, in text
    r.text = text
  File "C:\Users\LENOVO\Desktop\Academy\env\lib\site-packages\docx\oxml\text\run.py", line 129, in text
    _RunContentAppender.append_to_run_from_text(self, text)
  File "C:\Users\LENOVO\Desktop\Academy\env\lib\site-packages\docx\oxml\text\run.py", line 248, in append_to_run_from_text
    appender.add_text(text)
  File "C:\Users\LENOVO\Desktop\Academy\env\lib\site-packages\docx\oxml\text\run.py", line 252, in add_text
    for char in text:
TypeError: 'NoneType' object is not iterable
2025-03-17 15:22:24,548 - ERROR - Une erreur est survenue
Traceback (most recent call last):
  File "c:\Users\LENOVO\Desktop\Academy\main.py", line 444, in generer_word
    row_cells[j].text = text
  File "C:\Users\LENOVO\Desktop\Academy\env\lib\site-packages\docx\table.py", line 284, in text
    r.text = text
  File "C:\Users\LENOVO\Desktop\Academy\env\lib\site-packages\docx\oxml\text\run.py", line 129, in text
    _RunContentAppender.append_to_run_from_text(self, text)
  File "C:\Users\LENOVO\Desktop\Academy\env\lib\site-packages\docx\oxml\text\run.py", line 248, in append_to_run_from_text
    appender.add_text(text)
  File "C:\Users\LENOVO\Desktop\Academy\env\lib\site-packages\docx\oxml\text\run.py", line 252, in add_text
    for char in text:
TypeError: 'NoneType' object is not iterable
2025-03-17 15:22:24,580 - ERROR - Une erreur est survenue
Traceback (most recent call last):
  File "c:\Users\LENOVO\Desktop\Academy\main.py", line 444, in generer_word
    row_cells[j].text = text
  File "C:\Users\LENOVO\Desktop\Academy\env\lib\site-packages\docx\table.py", line 284, in text
    r.text = text
  File "C:\Users\LENOVO\Desktop\Academy\env\lib\site-packages\docx\oxml\text\run.py", line 129, in text
    _RunContentAppender.append_to_run_from_text(self, text)
  File "C:\Users\LENOVO\Desktop\Academy\env\lib\site-packages\docx\oxml\text\run.py", line 248, in append_to_run_from_text
    appender.add_text(text)
  File "C:\Users\LENOVO\Desktop\Academy\env\lib\site-packages\docx\oxml\text\run.py", line 252, in add_text
    for char in text:
TypeError: 'NoneType' object is not iterable
2025-03-17 15:22:24,595 - ERROR - Une erreur est survenue
Traceback (most recent call last):
  File "c:\Users\LENOVO\Desktop\Academy\main.py", line 444, in generer_word
    row_cells[j].text = text
  File "C:\Users\LENOVO\Desktop\Academy\env\lib\site-packages\docx\table.py", line 284, in text
    r.text = text
  File "C:\Users\LENOVO\Desktop\Academy\env\lib\site-packages\docx\oxml\text\run.py", line 129, in text
    _RunContentAppender.append_to_run_from_text(self, text)
  File "C:\Users\LENOVO\Desktop\Academy\env\lib\site-packages\docx\oxml\text\run.py", line 248, in append_to_run_from_text
    appender.add_text(text)
  File "C:\Users\LENOVO\Desktop\Academy\env\lib\site-packages\docx\oxml\text\run.py", line 252, in add_text
    for char in text:
TypeError: 'NoneType' object is not iterable
2025-03-17 15:22:24,627 - ERROR - Une erreur est survenue
Traceback (most recent call last):
  File "c:\Users\LENOVO\Desktop\Academy\main.py", line 444, in generer_word
    row_cells[j].text = text
  File "C:\Users\LENOVO\Desktop\Academy\env\lib\site-packages\docx\table.py", line 284, in text
    r.text = text
  File "C:\Users\LENOVO\Desktop\Academy\env\lib\site-packages\docx\oxml\text\run.py", line 129, in text
    _RunContentAppender.append_to_run_from_text(self, text)
  File "C:\Users\LENOVO\Desktop\Academy\env\lib\site-packages\docx\oxml\text\run.py", line 248, in append_to_run_from_text
    appender.add_text(text)
  File "C:\Users\LENOVO\Desktop\Academy\env\lib\site-packages\docx\oxml\text\run.py", line 252, in add_text
    for char in text:
TypeError: 'NoneType' object is not iterable
2025-03-17 15:22:24,658 - ERROR - Une erreur est survenue
Traceback (most recent call last):
  File "c:\Users\LENOVO\Desktop\Academy\main.py", line 444, in generer_word
    row_cells[j].text = text
  File "C:\Users\LENOVO\Desktop\Academy\env\lib\site-packages\docx\table.py", line 284, in text
    r.text = text
  File "C:\Users\LENOVO\Desktop\Academy\env\lib\site-packages\docx\oxml\text\run.py", line 129, in text
    _RunContentAppender.append_to_run_from_text(self, text)
  File "C:\Users\LENOVO\Desktop\Academy\env\lib\site-packages\docx\oxml\text\run.py", line 248, in append_to_run_from_text
    appender.add_text(text)
  File "C:\Users\LENOVO\Desktop\Academy\env\lib\site-packages\docx\oxml\text\run.py", line 252, in add_text
    for char in text:
TypeError: 'NoneType' object is not iterable
2025-03-17 15:22:24,768 - ERROR - Une erreur est survenue
Traceback (most recent call last):
  File "c:\Users\LENOVO\Desktop\Academy\main.py", line 444, in generer_word
    row_cells[j].text = text
  File "C:\Users\LENOVO\Desktop\Academy\env\lib\site-packages\docx\table.py", line 284, in text
    r.text = text
  File "C:\Users\LENOVO\Desktop\Academy\env\lib\site-packages\docx\oxml\text\run.py", line 129, in text
    _RunContentAppender.append_to_run_from_text(self, text)
  File "C:\Users\LENOVO\Desktop\Academy\env\lib\site-packages\docx\oxml\text\run.py", line 248, in append_to_run_from_text
    appender.add_text(text)
  File "C:\Users\LENOVO\Desktop\Academy\env\lib\site-packages\docx\oxml\text\run.py", line 252, in add_text
    for char in text:
TypeError: 'NoneType' object is not iterable
2025-03-17 15:22:24,800 - ERROR - Une erreur est survenue
Traceback (most recent call last):
  File "c:\Users\LENOVO\Desktop\Academy\main.py", line 444, in generer_word
    row_cells[j].text = text
  File "C:\Users\LENOVO\Desktop\Academy\env\lib\site-packages\docx\table.py", line 284, in text
    r.text = text
  File "C:\Users\LENOVO\Desktop\Academy\env\lib\site-packages\docx\oxml\text\run.py", line 129, in text
    _RunContentAppender.append_to_run_from_text(self, text)
  File "C:\Users\LENOVO\Desktop\Academy\env\lib\site-packages\docx\oxml\text\run.py", line 248, in append_to_run_from_text
    appender.add_text(text)
  File "C:\Users\LENOVO\Desktop\Academy\env\lib\site-packages\docx\oxml\text\run.py", line 252, in add_text
    for char in text:
TypeError: 'NoneType' object is not iterable
2025-03-17 15:22:24,831 - ERROR - Une erreur est survenue
Traceback (most recent call last):
  File "c:\Users\LENOVO\Desktop\Academy\main.py", line 444, in generer_word
    row_cells[j].text = text
  File "C:\Users\LENOVO\Desktop\Academy\env\lib\site-packages\docx\table.py", line 284, in text
    r.text = text
  File "C:\Users\LENOVO\Desktop\Academy\env\lib\site-packages\docx\oxml\text\run.py", line 129, in text
    _RunContentAppender.append_to_run_from_text(self, text)
  File "C:\Users\LENOVO\Desktop\Academy\env\lib\site-packages\docx\oxml\text\run.py", line 248, in append_to_run_from_text
    appender.add_text(text)
  File "C:\Users\LENOVO\Desktop\Academy\env\lib\site-packages\docx\oxml\text\run.py", line 252, in add_text
    for char in text:
TypeError: 'NoneType' object is not iterable
2025-03-17 15:22:24,863 - ERROR - Une erreur est survenue
Traceback (most recent call last):
  File "c:\Users\LENOVO\Desktop\Academy\main.py", line 444, in generer_word
    row_cells[j].text = text
  File "C:\Users\LENOVO\Desktop\Academy\env\lib\site-packages\docx\table.py", line 284, in text
    r.text = text
  File "C:\Users\LENOVO\Desktop\Academy\env\lib\site-packages\docx\oxml\text\run.py", line 129, in text
    _RunContentAppender.append_to_run_from_text(self, text)
  File "C:\Users\LENOVO\Desktop\Academy\env\lib\site-packages\docx\oxml\text\run.py", line 248, in append_to_run_from_text
    appender.add_text(text)
  File "C:\Users\LENOVO\Desktop\Academy\env\lib\site-packages\docx\oxml\text\run.py", line 252, in add_text
    for char in text:
TypeError: 'NoneType' object is not iterable
2025-03-17 15:22:24,909 - ERROR - Une erreur est survenue
Traceback (most recent call last):
  File "c:\Users\LENOVO\Desktop\Academy\main.py", line 444, in generer_word
    row_cells[j].text = text
  File "C:\Users\LENOVO\Desktop\Academy\env\lib\site-packages\docx\table.py", line 284, in text
    r.text = text
  File "C:\Users\LENOVO\Desktop\Academy\env\lib\site-packages\docx\oxml\text\run.py", line 129, in text
    _RunContentAppender.append_to_run_from_text(self, text)
  File "C:\Users\LENOVO\Desktop\Academy\env\lib\site-packages\docx\oxml\text\run.py", line 248, in append_to_run_from_text
    appender.add_text(text)
  File "C:\Users\LENOVO\Desktop\Academy\env\lib\site-packages\docx\oxml\text\run.py", line 252, in add_text
    for char in text:
TypeError: 'NoneType' object is not iterable
2025-03-17 15:22:24,941 - ERROR - Une erreur est survenue
Traceback (most recent call last):
  File "c:\Users\LENOVO\Desktop\Academy\main.py", line 444, in generer_word
    row_cells[j].text = text
  File "C:\Users\LENOVO\Desktop\Academy\env\lib\site-packages\docx\table.py", line 284, in text
    r.text = text
  File "C:\Users\LENOVO\Desktop\Academy\env\lib\site-packages\docx\oxml\text\run.py", line 129, in text
    _RunContentAppender.append_to_run_from_text(self, text)
  File "C:\Users\LENOVO\Desktop\Academy\env\lib\site-packages\docx\oxml\text\run.py", line 248, in append_to_run_from_text
    appender.add_text(text)
  File "C:\Users\LENOVO\Desktop\Academy\env\lib\site-packages\docx\oxml\text\run.py", line 252, in add_text
    for char in text:
TypeError: 'NoneType' object is not iterable
2025-03-17 15:22:25,868 - ERROR - Une erreur est survenue
Traceback (most recent call last):
  File "c:\Users\LENOVO\Desktop\Academy\main.py", line 444, in generer_word
    row_cells[j].text = text
  File "C:\Users\LENOVO\Desktop\Academy\env\lib\site-packages\docx\table.py", line 284, in text
    r.text = text
  File "C:\Users\LENOVO\Desktop\Academy\env\lib\site-packages\docx\oxml\text\run.py", line 129, in text
    _RunContentAppender.append_to_run_from_text(self, text)
  File "C:\Users\LENOVO\Desktop\Academy\env\lib\site-packages\docx\oxml\text\run.py", line 248, in append_to_run_from_text
    appender.add_text(text)
  File "C:\Users\LENOVO\Desktop\Academy\env\lib\site-packages\docx\oxml\text\run.py", line 252, in add_text
    for char in text:
TypeError: 'NoneType' object is not iterable
2025-03-17 15:22:25,930 - ERROR - Une erreur est survenue
Traceback (most recent call last):
  File "c:\Users\LENOVO\Desktop\Academy\main.py", line 444, in generer_word
    row_cells[j].text = text
  File "C:\Users\LENOVO\Desktop\Academy\env\lib\site-packages\docx\table.py", line 284, in text
    r.text = text
  File "C:\Users\LENOVO\Desktop\Academy\env\lib\site-packages\docx\oxml\text\run.py", line 129, in text
    _RunContentAppender.append_to_run_from_text(self, text)
  File "C:\Users\LENOVO\Desktop\Academy\env\lib\site-packages\docx\oxml\text\run.py", line 248, in append_to_run_from_text
    appender.add_text(text)
  File "C:\Users\LENOVO\Desktop\Academy\env\lib\site-packages\docx\oxml\text\run.py", line 252, in add_text
    for char in text:
TypeError: 'NoneType' object is not iterable
2025-03-17 15:22:26,480 - ERROR - Une erreur est survenue
Traceback (most recent call last):
  File "c:\Users\LENOVO\Desktop\Academy\main.py", line 444, in generer_word
    row_cells[j].text = text
  File "C:\Users\LENOVO\Desktop\Academy\env\lib\site-packages\docx\table.py", line 284, in text
    r.text = text
  File "C:\Users\LENOVO\Desktop\Academy\env\lib\site-packages\docx\oxml\text\run.py", line 129, in text
    _RunContentAppender.append_to_run_from_text(self, text)
  File "C:\Users\LENOVO\Desktop\Academy\env\lib\site-packages\docx\oxml\text\run.py", line 248, in append_to_run_from_text
    appender.add_text(text)
  File "C:\Users\LENOVO\Desktop\Academy\env\lib\site-packages\docx\oxml\text\run.py", line 252, in add_text
    for char in text:
TypeError: 'NoneType' object is not iterable
2025-03-17 15:22:26,511 - ERROR - Une erreur est survenue
Traceback (most recent call last):
  File "c:\Users\LENOVO\Desktop\Academy\main.py", line 444, in generer_word
    row_cells[j].text = text
  File "C:\Users\LENOVO\Desktop\Academy\env\lib\site-packages\docx\table.py", line 284, in text
    r.text = text
  File "C:\Users\LENOVO\Desktop\Academy\env\lib\site-packages\docx\oxml\text\run.py", line 129, in text
    _RunContentAppender.append_to_run_from_text(self, text)
  File "C:\Users\LENOVO\Desktop\Academy\env\lib\site-packages\docx\oxml\text\run.py", line 248, in append_to_run_from_text
    appender.add_text(text)
  File "C:\Users\LENOVO\Desktop\Academy\env\lib\site-packages\docx\oxml\text\run.py", line 252, in add_text
    for char in text:
TypeError: 'NoneType' object is not iterable
2025-03-17 15:22:28,018 - ERROR - Une erreur est survenue
Traceback (most recent call last):
  File "c:\Users\LENOVO\Desktop\Academy\main.py", line 444, in generer_word
    row_cells[j].text = text
  File "C:\Users\LENOVO\Desktop\Academy\env\lib\site-packages\docx\table.py", line 284, in text
    r.text = text
  File "C:\Users\LENOVO\Desktop\Academy\env\lib\site-packages\docx\oxml\text\run.py", line 129, in text
    _RunContentAppender.append_to_run_from_text(self, text)
  File "C:\Users\LENOVO\Desktop\Academy\env\lib\site-packages\docx\oxml\text\run.py", line 248, in append_to_run_from_text
    appender.add_text(text)
  File "C:\Users\LENOVO\Desktop\Academy\env\lib\site-packages\docx\oxml\text\run.py", line 252, in add_text
    for char in text:
TypeError: 'NoneType' object is not iterable
